Workbook

Sheet GIRIS_CIKIS
A1: TARIH | B1: ISLEM | C1: FIRMA | D1: STOK ISMI | E1: RENK | F1: MIKTAR
A2: 46043 | B2: GIRIS | C2: KOCAKPARK | D2: H:100CM SAGA EGIMLI KAYDIRAK | E2: YESIL | F2: 8
A3: 46043 | B3: GIRIS | C3: KOCAKPARK | D3: H:100CM SAGA EGIMLI KAYDIRAK | E3: SARI | F3: 4
A4: 46043 | B4: GIRIS | C4: KOCAKPARK | D4: H:100CM SAGA EGIMLI KAYDIRAK | E4: TURUNCU | F4: 4
A5: 46043 | B5: GIRIS | C5: KOCAKPARK | D5: H:200CM DUZ KAYDIRAK | E5: YESIL | F5: 3
A6: 46043 | B6: GIRIS | C6: KOCAKPARK | D6: H:200CM DUZ KAYDIRAK | E6: MOR | F6: 3
A7: 46043 | B7: GIRIS | C7: KOCAKPARK | D7: H:200CM DUZ KAYDIRAK | E7: SARI | F7: 3
A8: 46043 | B8: GIRIS | C8: KOCAKPARK | D8: H:200CM DUZ KAYDIRAK | E8: TURUNCU | F8: 2
A9: 46043 | B9: GIRIS | C9: KOCAKPARK | D9: H:200CM DUZ KAYDIRAK | E9: KAHVERENGI | F9: 2
A10: 46043 | B10: GIRIS | C10: MERIDA | D10: H:150CM DUZ KAYDIRAK | E10: YESIL | F10: 10
A11: 46043 | B11: GIRIS | C11: MERIDA | D11: H:150CM DUZ KAYDIRAK | E11: MOR | F11: 1
A12: 46043 | B12: GIRIS | C12: MERIDA | D12: H:150CM DUZ KAYDIRAK | E12: SARI | F12: 4
A13: 46043 | B13: GIRIS | C13: MERIDA | D13: H:150CM DUZ KAYDIRAK | E13: TURUNCU | F13: 7
... A76: 46043 | B76: GIRIS | C76: KOCAKPARK | D76: SALINCAK SEPETI (BLD. VE KURUM) | E76: YESIL | F76: 60

Sheet STOK
A1: FIRMA | B1: STOK ISMI | C1: DALDIRMA | D1: YESIL | E1: MOR | F1: ACIK SARI | G1: SARI | H1: TURUNCU | I1: KIRMIZI | J1: KAHVERENGI | K1: ACIK MOR | L1: GRI | M1: TURKUAZ | N1: SIYAH | O1: MAVI | P1: TOPLAM | Q1: BIRIM
A2: KOCAKPARK | B2: H:100CM SAGA EGIMLI KAYDIRAK | C2: {=IFERROR( SUM( IF( (GIRIS_CIKIS!$B$2:$B$1002="GIRIS")* (GIRIS_CIKIS!$C$2:$C$1002=$A2)* (GIRIS_CIKIS!$D$2:$D$1002=$B2)* (GIRIS_CIKIS!$E$2:$E$1002="DALDIRMA"), GIRIS_CIKIS!$F$2:$F$1002 ) ) - SUM( IF( (GIRIS_CIKIS!$B$2:$B$1002="CIKIS")* (GIRIS_CIKIS!$C$2:$C$1002=$A2)* (GIRIS_CIKIS!$D$2:$D$1002=$B2)* (GIRIS_CIKIS!$E$2:$E$1002="DALDIRMA"), GIRIS_CIKIS!$F$2:$F$1002 ) ),0)} -> 0 | D2: {=IFERROR( SUM( IF( (GIRIS_CIKIS!$B$2:$B$1002="GIRIS")* (GIRIS_CIKIS!$C$2:$C$1002=$A2)* (GIRIS_CIKIS!$D$2:$D$1002=$B2)* (GIRIS_CIKIS!$E$2:$E$1002="YESIL"), GIRIS_CIKIS!$F$2:$F$1002 ) ) - SUM( IF( (GIRIS_CIKIS!$B$2:$B$1002="CIKIS")* (GIRIS_CIKIS!$C$2:$C$1002=$A2)* (GIRIS_CIKIS!$D$2:$D$1002=$B2)* (GIRIS_CIKIS!$E$2:$E$1002="YESIL"), GIRIS_CIKIS!$F$2:$F$1002 ) ),0)} -> 8 | E2: {=IFERROR( SUM( IF( (GIRIS_CIKIS!$B$2:$B$1002="GIRIS")* (GIRIS_CIKIS!$C$2:$C$1002=$A2)* (GIRIS_CIKIS!$D$2:$D$1002=$B2)* (GIRIS_CIKIS!$E$2:$E$1002="MOR"), GIRIS_CIKIS!$F$2:$F$1002 ) ) - SUM( IF( (GIRIS_CIKIS!$B$2:$B$1002="CIKIS")* (GIRIS_CIKIS!$C$2:$C$1002=$A2)* (GIRIS_CIKIS!$D$2:$D$1002=$B2)* (GIRIS_CIKIS!$E$2:$E$1002="MOR"), GIRIS_CIKIS!$F$2:$F$1002 ) ),0)} -> 0 | F2: {=IFERROR( SUM( IF( (GIRIS_CIKIS!$B$2:$B$1002="GIRIS")* (GIRIS_CIKIS!$C$2:$C$1002=$A2)* (GIRIS_CIKIS!$D$2:$D$1002=$B2)* (GIRIS_CIKIS!$E$2:$E$1002="ACIK SARI"), GIRIS_CIKIS!$F$2:$F$1002 ) ) - SUM( IF( (GIRIS_CIKIS!$B$2:$B$1002="CIKIS")* (GIRIS_CIKIS!$C$2:$C$1002=$A2)* (GIRIS_CIKIS!$D$2:$D$1002=$B2)* (GIRIS_CIKIS!$E$2:$E$1002="ACIK SARI"), GIRIS_CIKIS!$F$2:$F$1002 ) ),0)} -> 0 | G2: {=IFERROR( SUM( IF( (GIRIS_CIKIS!$B$2:$B$1002="GIRIS")* (GIRIS_CIKIS!$C$2:$C$1002=$A2)* (GIRIS_CIKIS!$D$2:$D$1002=$B2)* (GIRIS_CIKIS!$E$2:$E$1002="SARI"), GIRIS_CIKIS!$F$2:$F$1002 ) ) - SUM( IF( (GIRIS_CIKIS!$B$2:$B$1002="CIKIS")* (GIRIS_CIKIS!$C$2:$C$1002=$A2)* (GIRIS_CIKIS!$D$2:$D$1002=$B2)* (GIRIS_CIKIS!$E$2:$E$1002="SARI"), GIRIS_CIKIS!$F$2:$F$1002 ) ),0)} -> 4 | H2: {=IFERROR( SUM( IF( (GIRIS_CIKIS!$B$2:$B$1002="GIRIS")* (GIRIS_CIKIS!$C$2:$C$1002=$A2)* (GIRIS_CIKIS!$D$2:$D$1002=$B2)* (GIRIS_CIKIS!$E$2:$E$1002="TURUNCU"), GIRIS_CIKIS!$F$2:$F$1002 ) ) - SUM( IF( (GIRIS_CIKIS!$B$2:$B$1002="CIKIS")* (GIRIS_CIKIS!$C$2:$C$1002=$A2)* (GIRIS_CIKIS!$D$2:$D$1002=$B2)* (GIRIS_CIKIS!$E$2:$E$1002="TURUNCU"), GIRIS_CIKIS!$F$2:$F$1002 ) ),0)} -> 4 | I2: {=IFERROR( SUM( IF( (GIRIS_CIKIS!$B$2:$B$1002="GIRIS")* (GIRIS_CIKIS!$C$2:$C$1002=$A2)* (GIRIS_CIKIS!$D$2:$D$1002=$B2)* (GIRIS_CIKIS!$E$2:$E$1002="KIRMIZI"), GIRIS_CIKIS!$F$2:$F$1002 ) ) - SUM( IF( (GIRIS_CIKIS!$B$2:$B$1002="CIKIS")* (GIRIS_CIKIS!$C$2:$C$1002=$A2)* (GIRIS_CIKIS!$D$2:$D$1002=$B2)* (GIRIS_CIKIS!$E$2:$E$1002="KIRMIZI"), GIRIS_CIKIS!$F$2:$F$1002 ) ),0)} -> 0 | J2: {=IFERROR( SUM( IF( (GIRIS_CIKIS!$B$2:$B$1002="GIRIS")* (GIRIS_CIKIS!$C$2:$C$1002=$A2)* (GIRIS_CIKIS!$D$2:$D$1002=$B2)* (GIRIS_CIKIS!$E$2:$E$1002="KAHVERENGI"), GIRIS_CIKIS!$F$2:$F$1002 ) ) - SUM( IF( (GIRIS_CIKIS!$B$2:$B$1002="CIKIS")* (GIRIS_CIKIS!$C$2:$C$1002=$A2)* (GIRIS_CIKIS!$D$2:$D$1002=$B2)* (GIRIS_CIKIS!$E$2:$E$1002="KAHVERENGI"), GIRIS_CIKIS!$F$2:$F$1002 ) ),0)} -> 0 | K2: {=IFERROR( SUM( IF( (GIRIS_CIKIS!$B$2:$B$1002="GIRIS")* (GIRIS_CIKIS!$C$2:$C$1002=$A2)* (GIRIS_CIKIS!$D$2:$D$1002=$B2)* (GIRIS_CIKIS!$E$2:$E$1002="ACIK MOR"), GIRIS_CIKIS!$F$2:$F$1002 ) ) - SUM( IF( (GIRIS_CIKIS!$B$2:$B$1002="CIKIS")* (GIRIS_CIKIS!$C$2:$C$1002=$A2)* (GIRIS_CIKIS!$D$2:$D$1002=$B2)* (GIRIS_CIKIS!$E$2:$E$1002="ACIK MOR"), GIRIS_CIKIS!$F$2:$F$1002 ) ),0)} -> 0 | L2: {=IFERROR( SUM( IF( (GIRIS_CIKIS!$B$2:$B$1002="GIRIS")* (GIRIS_CIKIS!$C$2:$C$1002=$A2)* (GIRIS_CIKIS!$D$2:$D$1002=$B2)* (GIRIS_CIKIS!$E$2:$E$1002="GRI"), GIRIS_CIKIS!$F$2:$F$1002 ) ) - SUM( IF( (GIRIS_CIKIS!$B$2:$B$1002="CIKIS")* (GIRIS_CIKIS!$C$2:$C$1002=$A2)* (GIRIS_CIKIS!$D$2:$D$1002=$B2)* (GIRIS_CIKIS!$E$2:$E$1002="GRI"), GIRIS_CIKIS!$F$2:$F$1002 ) ),0)} -> 0 | M2: {=IFERROR( SUM( IF( (GIRIS_CIKIS!$B$2:$B$1002="GIRIS")* (GIRIS_CIKIS!$C$2:$C$1002=$A2)* (GIRIS_CIKIS!$D$2:$D$1002=$B2)* (GIRIS_CIKIS!$E$2:$E$1002="TURKUAZ"), GIRIS_CIKIS!$F$2:$F$1002 ) ) - SUM( IF( (GIRIS_CIKIS!$B$2:$B$1002="CIKIS")* (GIRIS_CIKIS!$C$2:$C$1002=$A2)* (GIRIS_CIKIS!$D$2:$D$1002=$B2)* (GIRIS_CIKIS!$E$2:$E$1002="TURKUAZ"), GIRIS_CIKIS!$F$2:$F$1002 ) ),0)} -> 0 | N2: {=IFERROR( SUM( IF( (GIRIS_CIKIS!$B$2:$B$1002="GIRIS")* (GIRIS_CIKIS!$C$2:$C$1002=$A2)* (GIRIS_CIKIS!$D$2:$D$1002=$B2)* (GIRIS_CIKIS!$E$2:$E$1002="SIYAH"), GIRIS_CIKIS!$F$2:$F$1002 ) ) - SUM( IF( (GIRIS_CIKIS!$B$2:$B$1002="CIKIS")* (GIRIS_CIKIS!$C$2:$C$1002=$A2)* (GIRIS_CIKIS!$D$2:$D$1002=$B2)* (GIRIS_CIKIS!$E$2:$E$1002="SIYAH"), GIRIS_CIKIS!$F$2:$F$1002 ) ),0)} -> 0 | O2: {=IFERROR( SUM( IF( (GIRIS_CIKIS!$B$2:$B$1002="GIRIS")* (GIRIS_CIKIS!$C$2:$C$1002=$A2)* (GIRIS_CIKIS!$D$2:$D$1002=$B2)* (GIRIS_CIKIS!$E$2:$E$1002="MAVI"), GIRIS_CIKIS!$F$2:$F$1002 ) ) - SUM( IF( (GIRIS_CIKIS!$B$2:$B$1002="CIKIS")* (GIRIS_CIKIS!$C$2:$C$1002=$A2)* (GIRIS_CIKIS!$D$2:$D$1002=$B2)* (GIRIS_CIKIS!$E$2:$E$1002="MAVI"), GIRIS_CIKIS!$F$2:$F$1002 ) ),0)} -> 0 | P2: =SUM(C2:O2) -> 16 | Q2: ADET
A3: KOCAKPARK | B3: H:200CM DUZ KAYDIRAK | C3: {=IFERROR( SUM( IF( (GIRIS_CIKIS!$B$2:$B$1002="GIRIS")* (GIRIS_CIKIS!$C$2:$C$1002=$A3)* (GIRIS_CIKIS!$D$2:$D$1002=$B3)* (GIRIS_CIKIS!$E$2:$E$1002="DALDIRMA"), GIRIS_CIKIS!$F$2:$F$1002 ) ) - SUM( IF( (GIRIS_CIKIS!$B$2:$B$1002="CIKIS")* (GIRIS_CIKIS!$C$2:$C$1002=$A3)* (GIRIS_CIKIS!$D$2:$D$1002=$B3)* (GIRIS_CIKIS!$E$2:$E$1002="DALDIRMA"), GIRIS_CIKIS!$F$2:$F$1002 ) ),0)} -> 0 | D3: {=IFERROR( SUM( IF( (GIRIS_CIKIS!$B$2:$B$1002="GIRIS")* (GIRIS_CIKIS!$C$2:$C$1002=$A3)* (GIRIS_CIKIS!$D$2:$D$1002=$B3)* (GIRIS_CIKIS!$E$2:$E$1002="YESIL"), GIRIS_CIKIS!$F$2:$F$1002 ) ) - SUM( IF( (GIRIS_CIKIS!$B$2:$B$1002="CIKIS")* (GIRIS_CIKIS!$C$2:$C$1002=$A3)* (GIRIS_CIKIS!$D$2:$D$1002=$B3)* (GIRIS_CIKIS!$E$2:$E$1002="YESIL"), GIRIS_CIKIS!$F$2:$F$1002 ) ),0)} -> 3 | E3: {=IFERROR( SUM( IF( (GIRIS_CIKIS!$B$2:$B$1002="GIRIS")* (GIRIS_CIKIS!$C$2:$C$1002=$A3)* (GIRIS_CIKIS!$D$2:$D$1002=$B3)* (GIRIS_CIKIS!$E$2:$E$1002="MOR"), GIRIS_CIKIS!$F$2:$F$1002 ) ) - SUM( IF( (GIRIS_CIKIS!$B$2:$B$1002="CIKIS")* (GIRIS_CIKIS!$C$2:$C$1002=$A3)* (GIRIS_CIKIS!$D$2:$D$1002=$B3)* (GIRIS_CIKIS!$E$2:$E$1002="MOR"), GIRIS_CIKIS!$F$2:$F$1002 ) ),0)} -> 3 | F3: {=IFERROR( SUM( IF( (GIRIS_CIKIS!$B$2:$B$1002="GIRIS")* (GIRIS_CIKIS!$C$2:$C$1002=$A3)* (GIRIS_CIKIS!$D$2:$D$1002=$B3)* (GIRIS_CIKIS!$E$2:$E$1002="ACIK SARI"), GIRIS_CIKIS!$F$2:$F$1002 ) ) - SUM( IF( (GIRIS_CIKIS!$B$2:$B$1002="CIKIS")* (GIRIS_CIKIS!$C$2:$C$1002=$A3)* (GIRIS_CIKIS!$D$2:$D$1002=$B3)* (GIRIS_CIKIS!$E$2:$E$1002="ACIK SARI"), GIRIS_CIKIS!$F$2:$F$1002 ) ),0)} -> 0 | G3: {=IFERROR( SUM( IF( (GIRIS_CIKIS!$B$2:$B$1002="GIRIS")* (GIRIS_CIKIS!$C$2:$C$1002=$A3)* (GIRIS_CIKIS!$D$2:$D$1002=$B3)* (GIRIS_CIKIS!$E$2:$E$1002="SARI"), GIRIS_CIKIS!$F$2:$F$1002 ) ) - SUM( IF( (GIRIS_CIKIS!$B$2:$B$1002="CIKIS")* (GIRIS_CIKIS!$C$2:$C$1002=$A3)* (GIRIS_CIKIS!$D$2:$D$1002=$B3)* (GIRIS_CIKIS!$E$2:$E$1002="SARI"), GIRIS_CIKIS!$F$2:$F$1002 ) ),0)} -> 3 | H3: {=IFERROR( SUM( IF( (GIRIS_CIKIS!$B$2:$B$1002="GIRIS")* (GIRIS_CIKIS!$C$2:$C$1002=$A3)* (GIRIS_CIKIS!$D$2:$D$1002=$B3)* (GIRIS_CIKIS!$E$2:$E$1002="TURUNCU"), GIRIS_CIKIS!$F$2:$F$1002 ) ) - SUM( IF( (GIRIS_CIKIS!$B$2:$B$1002="CIKIS")* (GIRIS_CIKIS!$C$2:$C$1002=$A3)* (GIRIS_CIKIS!$D$2:$D$1002=$B3)* (GIRIS_CIKIS!$E$2:$E$1002="TURUNCU"), GIRIS_CIKIS!$F$2:$F$1002 ) ),0)} -> 2 | I3: {=IFERROR( SUM( IF( (GIRIS_CIKIS!$B$2:$B$1002="GIRIS")* (GIRIS_CIKIS!$C$2:$C$1002=$A3)* (GIRIS_CIKIS!$D$2:$D$1002=$B3)* (GIRIS_CIKIS!$E$2:$E$1002="KIRMIZI"), GIRIS_CIKIS!$F$2:$F$1002 ) ) - SUM( IF( (GIRIS_CIKIS!$B$2:$B$1002="CIKIS")* (GIRIS_CIKIS!$C$2:$C$1002=$A3)* (GIRIS_CIKIS!$D$2:$D$1002=$B3)* (GIRIS_CIKIS!$E$2:$E$1002="KIRMIZI"), GIRIS_CIKIS!$F$2:$F$1002 ) ),0)} -> 0 | J3: {=IFERROR( SUM( IF( (GIRIS_CIKIS!$B$2:$B$1002="GIRIS")* (GIRIS_CIKIS!$C$2:$C$1002=$A3)* (GIRIS_CIKIS!$D$2:$D$1002=$B3)* (GIRIS_CIKIS!$E$2:$E$1002="KAHVERENGI"), GIRIS_CIKIS!$F$2:$F$1002 ) ) - SUM( IF( (GIRIS_CIKIS!$B$2:$B$1002="CIKIS")* (GIRIS_CIKIS!$C$2:$C$1002=$A3)* (GIRIS_CIKIS!$D$2:$D$1002=$B3)* (GIRIS_CIKIS!$E$2:$E$1002="KAHVERENGI"), GIRIS_CIKIS!$F$2:$F$1002 ) ),0)} -> 2 | K3: {=IFERROR( SUM( IF( (GIRIS_CIKIS!$B$2:$B$1002="GIRIS")* (GIRIS_CIKIS!$C$2:$C$1002=$A3)* (GIRIS_CIKIS!$D$2:$D$1002=$B3)* (GIRIS_CIKIS!$E$2:$E$1002="ACIK MOR"), GIRIS_CIKIS!$F$2:$F$1002 ) ) - SUM( IF( (GIRIS_CIKIS!$B$2:$B$1002="CIKIS")* (GIRIS_CIKIS!$C$2:$C$1002=$A3)* (GIRIS_CIKIS!$D$2:$D$1002=$B3)* (GIRIS_CIKIS!$E$2:$E$1002="ACIK MOR"), GIRIS_CIKIS!$F$2:$F$1002 ) ),0)} -> 0 | L3: {=IFERROR( SUM( IF( (GIRIS_CIKIS!$B$2:$B$1002="GIRIS")* (GIRIS_CIKIS!$C$2:$C$1002=$A3)* (GIRIS_CIKIS!$D$2:$D$1002=$B3)* (GIRIS_CIKIS!$E$2:$E$1002="GRI"), GIRIS_CIKIS!$F$2:$F$1002 ) ) - SUM( IF( (GIRIS_CIKIS!$B$2:$B$1002="CIKIS")* (GIRIS_CIKIS!$C$2:$C$1002=$A3)* (GIRIS_CIKIS!$D$2:$D$1002=$B3)* (GIRIS_CIKIS!$E$2:$E$1002="GRI"), GIRIS_CIKIS!$F$2:$F$1002 ) ),0)} -> 0 | M3: {=IFERROR( SUM( IF( (GIRIS_CIKIS!$B$2:$B$1002="GIRIS")* (GIRIS_CIKIS!$C$2:$C$1002=$A3)* (GIRIS_CIKIS!$D$2:$D$1002=$B3)* (GIRIS_CIKIS!$E$2:$E$1002="TURKUAZ"), GIRIS_CIKIS!$F$2:$F$1002 ) ) - SUM( IF( (GIRIS_CIKIS!$B$2:$B$1002="CIKIS")* (GIRIS_CIKIS!$C$2:$C$1002=$A3)* (GIRIS_CIKIS!$D$2:$D$1002=$B3)* (GIRIS_CIKIS!$E$2:$E$1002="TURKUAZ"), GIRIS_CIKIS!$F$2:$F$1002 ) ),0)} -> 0 | N3: {=IFERROR( SUM( IF( (GIRIS_CIKIS!$B$2:$B$1002="GIRIS")* (GIRIS_CIKIS!$C$2:$C$1002=$A3)* (GIRIS_CIKIS!$D$2:$D$1002=$B3)* (GIRIS_CIKIS!$E$2:$E$1002="SIYAH"), GIRIS_CIKIS!$F$2:$F$1002 ) ) - SUM( IF( (GIRIS_CIKIS!$B$2:$B$1002="CIKIS")* (GIRIS_CIKIS!$C$2:$C$1002=$A3)* (GIRIS_CIKIS!$D$2:$D$1002=$B3)* (GIRIS_CIKIS!$E$2:$E$1002="SIYAH"), GIRIS_CIKIS!$F$2:$F$1002 ) ),0)} -> 0 | O3: {=IFERROR( SUM( IF( (GIRIS_CIKIS!$B$2:$B$1002="GIRIS")* (GIRIS_CIKIS!$C$2:$C$1002=$A3)* (GIRIS_CIKIS!$D$2:$D$1002=$B3)* (GIRIS_CIKIS!$E$2:$E$1002="MAVI"), GIRIS_CIKIS!$F$2:$F$1002 ) ) - SUM( IF( (GIRIS_CIKIS!$B$2:$B$1002="CIKIS")* (GIRIS_CIKIS!$C$2:$C$1002=$A3)* (GIRIS_CIKIS!$D$2:$D$1002=$B3)* (GIRIS_CIKIS!$E$2:$E$1002="MAVI"), GIRIS_CIKIS!$F$2:$F$1002 ) ),0)} -> 0 | P3: =SUM(C3:O3) -> 13 | Q3: ADET
A4: MERIDA | B4: H:150CM DUZ KAYDIRAK | C4: {=IFERROR( SUM( IF( (GIRIS_CIKIS!$B$2:$B$1002="GIRIS")* (GIRIS_CIKIS!$C$2:$C$1002=$A4)* (GIRIS_CIKIS!$D$2:$D$1002=$B4)* (GIRIS_CIKIS!$E$2:$E$1002="DALDIRMA"), GIRIS_CIKIS!$F$2:$F$1002 ) ) - SUM( IF( (GIRIS_CIKIS!$B$2:$B$1002="CIKIS")* (GIRIS_CIKIS!$C$2:$C$1002=$A4)* (GIRIS_CIKIS!$D$2:$D$1002=$B4)* (GIRIS_CIKIS!$E$2:$E$1002="DALDIRMA"), GIRIS_CIKIS!$F$2:$F$1002 ) ),0)} -> 0 | D4: {=IFERROR( SUM( IF( (GIRIS_CIKIS!$B$2:$B$1002="GIRIS")* (GIRIS_CIKIS!$C$2:$C$1002=$A4)* (GIRIS_CIKIS!$D$2:$D$1002=$B4)* (GIRIS_CIKIS!$E$2:$E$1002="YESIL"), GIRIS_CIKIS!$F$2:$F$1002 ) ) - SUM( IF( (GIRIS_CIKIS!$B$2:$B$1002="CIKIS")* (GIRIS_CIKIS!$C$2:$C$1002=$A4)* (GIRIS_CIKIS!$D$2:$D$1002=$B4)* (GIRIS_CIKIS!$E$2:$E$1002="YESIL"), GIRIS_CIKIS!$F$2:$F$1002 ) ),0)} -> 10 | E4: {=IFERROR( SUM( IF( (GIRIS_CIKIS!$B$2:$B$1002="GIRIS")* (GIRIS_CIKIS!$C$2:$C$1002=$A4)* (GIRIS_CIKIS!$D$2:$D$1002=$B4)* (GIRIS_CIKIS!$E$2:$E$1002="MOR"), GIRIS_CIKIS!$F$2:$F$1002 ) ) - SUM( IF( (GIRIS_CIKIS!$B$2:$B$1002="CIKIS")* (GIRIS_CIKIS!$C$2:$C$1002=$A4)* (GIRIS_CIKIS!$D$2:$D$1002=$B4)* (GIRIS_CIKIS!$E$2:$E$1002="MOR"), GIRIS_CIKIS!$F$2:$F$1002 ) ),0)} -> 1 | F4: {=IFERROR( SUM( IF( (GIRIS_CIKIS!$B$2:$B$1002="GIRIS")* (GIRIS_CIKIS!$C$2:$C$1002=$A4)* (GIRIS_CIKIS!$D$2:$D$1002=$B4)* (GIRIS_CIKIS!$E$2:$E$1002="ACIK SARI"), GIRIS_CIKIS!$F$2:$F$1002 ) ) - SUM( IF( (GIRIS_CIKIS!$B$2:$B$1002="CIKIS")* (GIRIS_CIKIS!$C$2:$C$1002=$A4)* (GIRIS_CIKIS!$D$2:$D$1002=$B4)* (GIRIS_CIKIS!$E$2:$E$1002="ACIK SARI"), GIRIS_CIKIS!$F$2:$F$1002 ) ),0)} -> 0 | G4: {=IFERROR( SUM( IF( (GIRIS_CIKIS!$B$2:$B$1002="GIRIS")* (GIRIS_CIKIS!$C$2:$C$1002=$A4)* (GIRIS_CIKIS!$D$2:$D$1002=$B4)* (GIRIS_CIKIS!$E$2:$E$1002="SARI"), GIRIS_CIKIS!$F$2:$F$1002 ) ) - SUM( IF( (GIRIS_CIKIS!$B$2:$B$1002="CIKIS")* (GIRIS_CIKIS!$C$2:$C$1002=$A4)* (GIRIS_CIKIS!$D$2:$D$1002=$B4)* (GIRIS_CIKIS!$E$2:$E$1002="SARI"), GIRIS_CIKIS!$F$2:$F$1002 ) ),0)} -> 4 | H4: {=IFERROR( SUM( IF( (GIRIS_CIKIS!$B$2:$B$1002="GIRIS")* (GIRIS_CIKIS!$C$2:$C$1002=$A4)* (GIRIS_CIKIS!$D$2:$D$1002=$B4)* (GIRIS_CIKIS!$E$2:$E$1002="TURUNCU"), GIRIS_CIKIS!$F$2:$F$1002 ) ) - SUM( IF( (GIRIS_CIKIS!$B$2:$B$1002="CIKIS")* (GIRIS_CIKIS!$C$2:$C$1002=$A4)* (GIRIS_CIKIS!$D$2:$D$1002=$B4)* (GIRIS_CIKIS!$E$2:$E$1002="TURUNCU"), GIRIS_CIKIS!$F$2:$F$1002 ) ),0)} -> 7 | I4: {=IFERROR( SUM( IF( (GIRIS_CIKIS!$B$2:$B$1002="GIRIS")* (GIRIS_CIKIS!$C$2:$C$1002=$A4)* (GIRIS_CIKIS!$D$2:$D$1002=$B4)* (GIRIS_CIKIS!$E$2:$E$1002="KIRMIZI"), GIRIS_CIKIS!$F$2:$F$1002 ) ) - SUM( IF( (GIRIS_CIKIS!$B$2:$B$1002="CIKIS")* (GIRIS_CIKIS!$C$2:$C$1002=$A4)* (GIRIS_CIKIS!$D$2:$D$1002=$B4)* (GIRIS_CIKIS!$E$2:$E$1002="KIRMIZI"), GIRIS_CIKIS!$F$2:$F$1002 ) ),0)} -> 0 | J4: {=IFERROR( SUM( IF( (GIRIS_CIKIS!$B$2:$B$1002="GIRIS")* (GIRIS_CIKIS!$C$2:$C$1002=$A4)* (GIRIS_CIKIS!$D$2:$D$1002=$B4)* (GIRIS_CIKIS!$E$2:$E$1002="KAHVERENGI"), GIRIS_CIKIS!$F$2:$F$1002 ) ) - SUM( IF( (GIRIS_CIKIS!$B$2:$B$1002="CIKIS")* (GIRIS_CIKIS!$C$2:$C$1002=$A4)* (GIRIS_CIKIS!$D$2:$D$1002=$B4)* (GIRIS_CIKIS!$E$2:$E$1002="KAHVERENGI"), GIRIS_CIKIS!$F$2:$F$1002 ) ),0)} -> 0 | K4: {=IFERROR( SUM( IF( (GIRIS_CIKIS!$B$2:$B$1002="GIRIS")* (GIRIS_CIKIS!$C$2:$C$1002=$A4)* (GIRIS_CIKIS!$D$2:$D$1002=$B4)* (GIRIS_CIKIS!$E$2:$E$1002="ACIK MOR"), GIRIS_CIKIS!$F$2:$F$1002 ) ) - SUM( IF( (GIRIS_CIKIS!$B$2:$B$1002="CIKIS")* (GIRIS_CIKIS!$C$2:$C$1002=$A4)* (GIRIS_CIKIS!$D$2:$D$1002=$B4)* (GIRIS_CIKIS!$E$2:$E$1002="ACIK MOR"), GIRIS_CIKIS!$F$2:$F$1002 ) ),0)} -> 0 | L4: {=IFERROR( SUM( IF( (GIRIS_CIKIS!$B$2:$B$1002="GIRIS")* (GIRIS_CIKIS!$C$2:$C$1002=$A4)* (GIRIS_CIKIS!$D$2:$D$1002=$B4)* (GIRIS_CIKIS!$E$2:$E$1002="GRI"), GIRIS_CIKIS!$F$2:$F$1002 ) ) - SUM( IF( (GIRIS_CIKIS!$B$2:$B$1002="CIKIS")* (GIRIS_CIKIS!$C$2:$C$1002=$A4)* (GIRIS_CIKIS!$D$2:$D$1002=$B4)* (GIRIS_CIKIS!$E$2:$E$1002="GRI"), GIRIS_CIKIS!$F$2:$F$1002 ) ),0)} -> 0 | M4: {=IFERROR( SUM( IF( (GIRIS_CIKIS!$B$2:$B$1002="GIRIS")* (GIRIS_CIKIS!$C$2:$C$1002=$A4)* (GIRIS_CIKIS!$D$2:$D$1002=$B4)* (GIRIS_CIKIS!$E$2:$E$1002="TURKUAZ"), GIRIS_CIKIS!$F$2:$F$1002 ) ) - SUM( IF( (GIRIS_CIKIS!$B$2:$B$1002="CIKIS")* (GIRIS_CIKIS!$C$2:$C$1002=$A4)* (GIRIS_CIKIS!$D$2:$D$1002=$B4)* (GIRIS_CIKIS!$E$2:$E$1002="TURKUAZ"), GIRIS_CIKIS!$F$2:$F$1002 ) ),0)} -> 0 | N4: {=IFERROR( SUM( IF( (GIRIS_CIKIS!$B$2:$B$1002="GIRIS")* (GIRIS_CIKIS!$C$2:$C$1002=$A4)* (GIRIS_CIKIS!$D$2:$D$1002=$B4)* (GIRIS_CIKIS!$E$2:$E$1002="SIYAH"), GIRIS_CIKIS!$F$2:$F$1002 ) ) - SUM( IF( (GIRIS_CIKIS!$B$2:$B$1002="CIKIS")* (GIRIS_CIKIS!$C$2:$C$1002=$A4)* (GIRIS_CIKIS!$D$2:$D$1002=$B4)* (GIRIS_CIKIS!$E$2:$E$1002="SIYAH"), GIRIS_CIKIS!$F$2:$F$1002 ) ),0)} -> 0 | O4: {=IFERROR( SUM( IF( (GIRIS_CIKIS!$B$2:$B$1002="GIRIS")* (GIRIS_CIKIS!$C$2:$C$1002=$A4)* (GIRIS_CIKIS!$D$2:$D$1002=$B4)* (GIRIS_CIKIS!$E$2:$E$1002="MAVI"), GIRIS_CIKIS!$F$2:$F$1002 ) ) - SUM( IF( (GIRIS_CIKIS!$B$2:$B$1002="CIKIS")* (GIRIS_CIKIS!$C$2:$C$1002=$A4)* (GIRIS_CIKIS!$D$2:$D$1002=$B4)* (GIRIS_CIKIS!$E$2:$E$1002="MAVI"), GIRIS_CIKIS!$F$2:$F$1002 ) ),0)} -> 0 | P4: =SUM(C4:O4) -> 22 | Q4: ADET
A5: MERIDA | B5: H:100CM TEKLI DUZ KAYDIRAK | C5: {=IFERROR( SUM( IF( (GIRIS_CIKIS!$B$2:$B$1002="GIRIS")* (GIRIS_CIKIS!$C$2:$C$1002=$A5)* (GIRIS_CIKIS!$D$2:$D$1002=$B5)* (GIRIS_CIKIS!$E$2:$E$1002="DALDIRMA"), GIRIS_CIKIS!$F$2:$F$1002 ) ) - SUM( IF( (GIRIS_CIKIS!$B$2:$B$1002="CIKIS")* (GIRIS_CIKIS!$C$2:$C$1002=$A5)* (GIRIS_CIKIS!$D$2:$D$1002=$B5)* (GIRIS_CIKIS!$E$2:$E$1002="DALDIRMA"), GIRIS_CIKIS!$F$2:$F$1002 ) ),0)} -> 0 | D5: {=IFERROR( SUM( IF( (GIRIS_CIKIS!$B$2:$B$1002="GIRIS")* (GIRIS_CIKIS!$C$2:$C$1002=$A5)* (GIRIS_CIKIS!$D$2:$D$1002=$B5)* (GIRIS_CIKIS!$E$2:$E$1002="YESIL"), GIRIS_CIKIS!$F$2:$F$1002 ) ) - SUM( IF( (GIRIS_CIKIS!$B$2:$B$1002="CIKIS")* (GIRIS_CIKIS!$C$2:$C$1002=$A5)* (GIRIS_CIKIS!$D$2:$D$1002=$B5)* (GIRIS_CIKIS!$E$2:$E$1002="YESIL"), GIRIS_CIKIS!$F$2:$F$1002 ) ),0)} -> 3 | E5: {=IFERROR( SUM( IF( (GIRIS_CIKIS!$B$2:$B$1002="GIRIS")* (GIRIS_CIKIS!$C$2:$C$1002=$A5)* (GIRIS_CIKIS!$D$2:$D$1002=$B5)* (GIRIS_CIKIS!$E$2:$E$1002="MOR"), GIRIS_CIKIS!$F$2:$F$1002 ) ) - SUM( IF( (GIRIS_CIKIS!$B$2:$B$1002="CIKIS")* (GIRIS_CIKIS!$C$2:$C$1002=$A5)* (GIRIS_CIKIS!$D$2:$D$1002=$B5)* (GIRIS_CIKIS!$E$2:$E$1002="MOR"), GIRIS_CIKIS!$F$2:$F$1002 ) ),0)} -> 0 | F5: {=IFERROR( SUM( IF( (GIRIS_CIKIS!$B$2:$B$1002="GIRIS")* (GIRIS_CIKIS!$C$2:$C$1002=$A5)* (GIRIS_CIKIS!$D$2:$D$1002=$B5)* (GIRIS_CIKIS!$E$2:$E$1002="ACIK SARI"), GIRIS_CIKIS!$F$2:$F$1002 ) ) - SUM( IF( (GIRIS_CIKIS!$B$2:$B$1002="CIKIS")* (GIRIS_CIKIS!$C$2:$C$1002=$A5)* (GIRIS_CIKIS!$D$2:$D$1002=$B5)* (GIRIS_CIKIS!$E$2:$E$1002="ACIK SARI"), GIRIS_CIKIS!$F$2:$F$1002 ) ),0)} -> 0 | G5: {=IFERROR( SUM( IF( (GIRIS_CIKIS!$B$2:$B$1002="GIRIS")* (GIRIS_CIKIS!$C$2:$C$1002=$A5)* (GIRIS_CIKIS!$D$2:$D$1002=$B5)* (GIRIS_CIKIS!$E$2:$E$1002="SARI"), GIRIS_CIKIS!$F$2:$F$1002 ) ) - SUM( IF( (GIRIS_CIKIS!$B$2:$B$1002="CIKIS")* (GIRIS_CIKIS!$C$2:$C$1002=$A5)* (GIRIS_CIKIS!$D$2:$D$1002=$B5)* (GIRIS_CIKIS!$E$2:$E$1002="SARI"), GIRIS_CIKIS!$F$2:$F$1002 ) ),0)} -> 8 | H5: {=IFERROR( SUM( IF( (GIRIS_CIKIS!$B$2:$B$1002="GIRIS")* (GIRIS_CIKIS!$C$2:$C$1002=$A5)* (GIRIS_CIKIS!$D$2:$D$1002=$B5)* (GIRIS_CIKIS!$E$2:$E$1002="TURUNCU"), GIRIS_CIKIS!$F$2:$F$1002 ) ) - SUM( IF( (GIRIS_CIKIS!$B$2:$B$1002="CIKIS")* (GIRIS_CIKIS!$C$2:$C$1002=$A5)* (GIRIS_CIKIS!$D$2:$D$1002=$B5)* (GIRIS_CIKIS!$E$2:$E$1002="TURUNCU"), GIRIS_CIKIS!$F$2:$F$1002 ) ),0)} -> 0 | I5: {=IFERROR( SUM( IF( (GIRIS_CIKIS!$B$2:$B$1002="GIRIS")* (GIRIS_CIKIS!$C$2:$C$1002=$A5)* (GIRIS_CIKIS!$D$2:$D$1002=$B5)* (GIRIS_CIKIS!$E$2:$E$1002="KIRMIZI"), GIRIS_CIKIS!$F$2:$F$1002 ) ) - SUM( IF( (GIRIS_CIKIS!$B$2:$B$1002="CIKIS")* (GIRIS_CIKIS!$C$2:$C$1002=$A5)* (GIRIS_CIKIS!$D$2:$D$1002=$B5)* (GIRIS_CIKIS!$E$2:$E$1002="KIRMIZI"), GIRIS_CIKIS!$F$2:$F$1002 ) ),0)} -> 0 | J5: {=IFERROR( SUM( IF( (GIRIS_CIKIS!$B$2:$B$1002="GIRIS")* (GIRIS_CIKIS!$C$2:$C$1002=$A5)* (GIRIS_CIKIS!$D$2:$D$1002=$B5)* (GIRIS_CIKIS!$E$2:$E$1002="KAHVERENGI"), GIRIS_CIKIS!$F$2:$F$1002 ) ) - SUM( IF( (GIRIS_CIKIS!$B$2:$B$1002="CIKIS")* (GIRIS_CIKIS!$C$2:$C$1002=$A5)* (GIRIS_CIKIS!$D$2:$D$1002=$B5)* (GIRIS_CIKIS!$E$2:$E$1002="KAHVERENGI"), GIRIS_CIKIS!$F$2:$F$1002 ) ),0)} -> 0 | K5: {=IFERROR( SUM( IF( (GIRIS_CIKIS!$B$2:$B$1002="GIRIS")* (GIRIS_CIKIS!$C$2:$C$1002=$A5)* (GIRIS_CIKIS!$D$2:$D$1002=$B5)* (GIRIS_CIKIS!$E$2:$E$1002="ACIK MOR"), GIRIS_CIKIS!$F$2:$F$1002 ) ) - SUM( IF( (GIRIS_CIKIS!$B$2:$B$1002="CIKIS")* (GIRIS_CIKIS!$C$2:$C$1002=$A5)* (GIRIS_CIKIS!$D$2:$D$1002=$B5)* (GIRIS_CIKIS!$E$2:$E$1002="ACIK MOR"), GIRIS_CIKIS!$F$2:$F$1002 ) ),0)} -> 0 | L5: {=IFERROR( SUM( IF( (GIRIS_CIKIS!$B$2:$B$1002="GIRIS")* (GIRIS_CIKIS!$C$2:$C$1002=$A5)* (GIRIS_CIKIS!$D$2:$D$1002=$B5)* (GIRIS_CIKIS!$E$2:$E$1002="GRI"), GIRIS_CIKIS!$F$2:$F$1002 ) ) - SUM( IF( (GIRIS_CIKIS!$B$2:$B$1002="CIKIS")* (GIRIS_CIKIS!$C$2:$C$1002=$A5)* (GIRIS_CIKIS!$D$2:$D$1002=$B5)* (GIRIS_CIKIS!$E$2:$E$1002="GRI"), GIRIS_CIKIS!$F$2:$F$1002 ) ),0)} -> 0 | M5: {=IFERROR( SUM( IF( (GIRIS_CIKIS!$B$2:$B$1002="GIRIS")* (GIRIS_CIKIS!$C$2:$C$1002=$A5)* (GIRIS_CIKIS!$D$2:$D$1002=$B5)* (GIRIS_CIKIS!$E$2:$E$1002="TURKUAZ"), GIRIS_CIKIS!$F$2:$F$1002 ) ) - SUM( IF( (GIRIS_CIKIS!$B$2:$B$1002="CIKIS")* (GIRIS_CIKIS!$C$2:$C$1002=$A5)* (GIRIS_CIKIS!$D$2:$D$1002=$B5)* (GIRIS_CIKIS!$E$2:$E$1002="TURKUAZ"), GIRIS_CIKIS!$F$2:$F$1002 ) ),0)} -> 0 | N5: {=IFERROR( SUM( IF( (GIRIS_CIKIS!$B$2:$B$1002="GIRIS")* (GIRIS_CIKIS!$C$2:$C$1002=$A5)* (GIRIS_CIKIS!$D$2:$D$1002=$B5)* (GIRIS_CIKIS!$E$2:$E$1002="SIYAH"), GIRIS_CIKIS!$F$2:$F$1002 ) ) - SUM( IF( (GIRIS_CIKIS!$B$2:$B$1002="CIKIS")* (GIRIS_CIKIS!$C$2:$C$1002=$A5)* (GIRIS_CIKIS!$D$2:$D$1002=$B5)* (GIRIS_CIKIS!$E$2:$E$1002="SIYAH"), GIRIS_CIKIS!$F$2:$F$1002 ) ),0)} -> 0 | O5: {=IFERROR( SUM( IF( (GIRIS_CIKIS!$B$2:$B$1002="GIRIS")* (GIRIS_CIKIS!$C$2:$C$1002=$A5)* (GIRIS_CIKIS!$D$2:$D$1002=$B5)* (GIRIS_CIKIS!$E$2:$E$1002="MAVI"), GIRIS_CIKIS!$F$2:$F$1002 ) ) - SUM( IF( (GIRIS_CIKIS!$B$2:$B$1002="CIKIS")* (GIRIS_CIKIS!$C$2:$C$1002=$A5)* (GIRIS_CIKIS!$D$2:$D$1002=$B5)* (GIRIS_CIKIS!$E$2:$E$1002="MAVI"), GIRIS_CIKIS!$F$2:$F$1002 ) ),0)} -> 0 | P5: =SUM(C5:O5) -> 11 | Q5: ADET
A6: KENDI KALIBIMIZ | B6: H:150CM SPIRAL KAYDIRAK | C6: {=IFERROR( SUM( IF( (GIRIS_CIKIS!$B$2:$B$1002="GIRIS")* (GIRIS_CIKIS!$C$2:$C$1002=$A6)* (GIRIS_CIKIS!$D$2:$D$1002=$B6)* (GIRIS_CIKIS!$E$2:$E$1002="DALDIRMA"), GIRIS_CIKIS!$F$2:$F$1002 ) ) - SUM( IF( (GIRIS_CIKIS!$B$2:$B$1002="CIKIS")* (GIRIS_CIKIS!$C$2:$C$1002=$A6)* (GIRIS_CIKIS!$D$2:$D$1002=$B6)* (GIRIS_CIKIS!$E$2:$E$1002="DALDIRMA"), GIRIS_CIKIS!$F$2:$F$1002 ) ),0)} -> 0 | D6: {=IFERROR( SUM( IF( (GIRIS_CIKIS!$B$2:$B$1002="GIRIS")* (GIRIS_CIKIS!$C$2:$C$1002=$A6)* (GIRIS_CIKIS!$D$2:$D$1002=$B6)* (GIRIS_CIKIS!$E$2:$E$1002="YESIL"), GIRIS_CIKIS!$F$2:$F$1002 ) ) - SUM( IF( (GIRIS_CIKIS!$B$2:$B$1002="CIKIS")* (GIRIS_CIKIS!$C$2:$C$1002=$A6)* (GIRIS_CIKIS!$D$2:$D$1002=$B6)* (GIRIS_CIKIS!$E$2:$E$1002="YESIL"), GIRIS_CIKIS!$F$2:$F$1002 ) ),0)} -> 6 | E6: {=IFERROR( SUM( IF( (GIRIS_CIKIS!$B$2:$B$1002="GIRIS")* (GIRIS_CIKIS!$C$2:$C$1002=$A6)* (GIRIS_CIKIS!$D$2:$D$1002=$B6)* (GIRIS_CIKIS!$E$2:$E$1002="MOR"), GIRIS_CIKIS!$F$2:$F$1002 ) ) - SUM( IF( (GIRIS_CIKIS!$B$2:$B$1002="CIKIS")* (GIRIS_CIKIS!$C$2:$C$1002=$A6)* (GIRIS_CIKIS!$D$2:$D$1002=$B6)* (GIRIS_CIKIS!$E$2:$E$1002="MOR"), GIRIS_CIKIS!$F$2:$F$1002 ) ),0)} -> 7 | F6: {=IFERROR( SUM( IF( (GIRIS_CIKIS!$B$2:$B$1002="GIRIS")* (GIRIS_CIKIS!$C$2:$C$1002=$A6)* (GIRIS_CIKIS!$D$2:$D$1002=$B6)* (GIRIS_CIKIS!$E$2:$E$1002="ACIK SARI"), GIRIS_CIKIS!$F$2:$F$1002 ) ) - SUM( IF( (GIRIS_CIKIS!$B$2:$B$1002="CIKIS")* (GIRIS_CIKIS!$C$2:$C$1002=$A6)* (GIRIS_CIKIS!$D$2:$D$1002=$B6)* (GIRIS_CIKIS!$E$2:$E$1002="ACIK SARI"), GIRIS_CIKIS!$F$2:$F$1002 ) ),0)} -> 2 | G6: {=IFERROR( SUM( IF( (GIRIS_CIKIS!$B$2:$B$1002="GIRIS")* (GIRIS_CIKIS!$C$2:$C$1002=$A6)* (GIRIS_CIKIS!$D$2:$D$1002=$B6)* (GIRIS_CIKIS!$E$2:$E$1002="SARI"), GIRIS_CIKIS!$F$2:$F$1002 ) ) - SUM( IF( (GIRIS_CIKIS!$B$2:$B$1002="CIKIS")* (GIRIS_CIKIS!$C$2:$C$1002=$A6)* (GIRIS_CIKIS!$D$2:$D$1002=$B6)* (GIRIS_CIKIS!$E$2:$E$1002="SARI"), GIRIS_CIKIS!$F$2:$F$1002 ) ),0)} -> 4 | H6: {=IFERROR( SUM( IF( (GIRIS_CIKIS!$B$2:$B$1002="GIRIS")* (GIRIS_CIKIS!$C$2:$C$1002=$A6)* (GIRIS_CIKIS!$D$2:$D$1002=$B6)* (GIRIS_CIKIS!$E$2:$E$1002="TURUNCU"), GIRIS_CIKIS!$F$2:$F$1002 ) ) - SUM( IF( (GIRIS_CIKIS!$B$2:$B$1002="CIKIS")* (GIRIS_CIKIS!$C$2:$C$1002=$A6)* (GIRIS_CIKIS!$D$2:$D$1002=$B6)* (GIRIS_CIKIS!$E$2:$E$1002="TURUNCU"), GIRIS_CIKIS!$F$2:$F$1002 ) ),0)} -> 2 | I6: {=IFERROR( SUM( IF( (GIRIS_CIKIS!$B$2:$B$1002="GIRIS")* (GIRIS_CIKIS!$C$2:$C$1002=$A6)* (GIRIS_CIKIS!$D$2:$D$1002=$B6)* (GIRIS_CIKIS!$E$2:$E$1002="KIRMIZI"), GIRIS_CIKIS!$F$2:$F$1002 ) ) - SUM( IF( (GIRIS_CIKIS!$B$2:$B$1002="CIKIS")* (GIRIS_CIKIS!$C$2:$C$1002=$A6)* (GIRIS_CIKIS!$D$2:$D$1002=$B6)* (GIRIS_CIKIS!$E$2:$E$1002="KIRMIZI"), GIRIS_CIKIS!$F$2:$F$1002 ) ),0)} -> 0 | J6: {=IFERROR( SUM( IF( (GIRIS_CIKIS!$B$2:$B$1002="GIRIS")* (GIRIS_CIKIS!$C$2:$C$1002=$A6)* (GIRIS_CIKIS!$D$2:$D$1002=$B6)* (GIRIS_CIKIS!$E$2:$E$1002="KAHVERENGI"), GIRIS_CIKIS!$F$2:$F$1002 ) ) - SUM( IF( (GIRIS_CIKIS!$B$2:$B$1002="CIKIS")* (GIRIS_CIKIS!$C$2:$C$1002=$A6)* (GIRIS_CIKIS!$D$2:$D$1002=$B6)* (GIRIS_CIKIS!$E$2:$E$1002="KAHVERENGI"), GIRIS_CIKIS!$F$2:$F$1002 ) ),0)} -> 0 | K6: {=IFERROR( SUM( IF( (GIRIS_CIKIS!$B$2:$B$1002="GIRIS")* (GIRIS_CIKIS!$C$2:$C$1002=$A6)* (GIRIS_CIKIS!$D$2:$D$1002=$B6)* (GIRIS_CIKIS!$E$2:$E$1002="ACIK MOR"), GIRIS_CIKIS!$F$2:$F$1002 ) ) - SUM( IF( (GIRIS_CIKIS!$B$2:$B$1002="CIKIS")* (GIRIS_CIKIS!$C$2:$C$1002=$A6)* (GIRIS_CIKIS!$D$2:$D$1002=$B6)* (GIRIS_CIKIS!$E$2:$E$1002="ACIK MOR"), GIRIS_CIKIS!$F$2:$F$1002 ) ),0)} -> 2 | L6: {=IFERROR( SUM( IF( (GIRIS_CIKIS!$B$2:$B$1002="GIRIS")* (GIRIS_CIKIS!$C$2:$C$1002=$A6)* (GIRIS_CIKIS!$D$2:$D$1002=$B6)* (GIRIS_CIKIS!$E$2:$E$1002="GRI"), GIRIS_CIKIS!$F$2:$F$1002 ) ) - SUM( IF( (GIRIS_CIKIS!$B$2:$B$1002="CIKIS")* (GIRIS_CIKIS!$C$2:$C$1002=$A6)* (GIRIS_CIKIS!$D$2:$D$1002=$B6)* (GIRIS_CIKIS!$E$2:$E$1002="GRI"), GIRIS_CIKIS!$F$2:$F$1002 ) ),0)} -> 0 | M6: {=IFERROR( SUM( IF( (GIRIS_CIKIS!$B$2:$B$1002="GIRIS")* (GIRIS_CIKIS!$C$2:$C$1002=$A6)* (GIRIS_CIKIS!$D$2:$D$1002=$B6)* (GIRIS_CIKIS!$E$2:$E$1002="TURKUAZ"), GIRIS_CIKIS!$F$2:$F$1002 ) ) - SUM( IF( (GIRIS_CIKIS!$B$2:$B$1002="CIKIS")* (GIRIS_CIKIS!$C$2:$C$1002=$A6)* (GIRIS_CIKIS!$D$2:$D$1002=$B6)* (GIRIS_CIKIS!$E$2:$E$1002="TURKUAZ"), GIRIS_CIKIS!$F$2:$F$1002 ) ),0)} -> 0 | N6: {=IFERROR( SUM( IF( (GIRIS_CIKIS!$B$2:$B$1002="GIRIS")* (GIRIS_CIKIS!$C$2:$C$1002=$A6)* (GIRIS_CIKIS!$D$2:$D$1002=$B6)* (GIRIS_CIKIS!$E$2:$E$1002="SIYAH"), GIRIS_CIKIS!$F$2:$F$1002 ) ) - SUM( IF( (GIRIS_CIKIS!$B$2:$B$1002="CIKIS")* (GIRIS_CIKIS!$C$2:$C$1002=$A6)* (GIRIS_CIKIS!$D$2:$D$1002=$B6)* (GIRIS_CIKIS!$E$2:$E$1002="SIYAH"), GIRIS_CIKIS!$F$2:$F$1002 ) ),0)} -> 0 | O6: {=IFERROR( SUM( IF( (GIRIS_CIKIS!$B$2:$B$1002="GIRIS")* (GIRIS_CIKIS!$C$2:$C$1002=$A6)* (GIRIS_CIKIS!$D$2:$D$1002=$B6)* (GIRIS_CIKIS!$E$2:$E$1002="MAVI"), GIRIS_CIKIS!$F$2:$F$1002 ) ) - SUM( IF( (GIRIS_CIKIS!$B$2:$B$1002="CIKIS")* (GIRIS_CIKIS!$C$2:$C$1002=$A6)* (GIRIS_CIKIS!$D$2:$D$1002=$B6)* (GIRIS_CIKIS!$E$2:$E$1002="MAVI"), GIRIS_CIKIS!$F$2:$F$1002 ) ),0)} -> 0 | P6: =SUM(C6:O6) -> 23 | Q6: ADET
A7: MERIDA | B7: H:100CM DUZ DALGALI KAYDIRAK | C7: {=IFERROR( SUM( IF( (GIRIS_CIKIS!$B$2:$B$1002="GIRIS")* (GIRIS_CIKIS!$C$2:$C$1002=$A7)* (GIRIS_CIKIS!$D$2:$D$1002=$B7)* (GIRIS_CIKIS!$E$2:$E$1002="DALDIRMA"), GIRIS_CIKIS!$F$2:$F$1002 ) ) - SUM( IF( (GIRIS_CIKIS!$B$2:$B$1002="CIKIS")* (GIRIS_CIKIS!$C$2:$C$1002=$A7)* (GIRIS_CIKIS!$D$2:$D$1002=$B7)* (GIRIS_CIKIS!$E$2:$E$1002="DALDIRMA"), GIRIS_CIKIS!$F$2:$F$1002 ) ),0)} -> 0 | D7: {=IFERROR( SUM( IF( (GIRIS_CIKIS!$B$2:$B$1002="GIRIS")* (GIRIS_CIKIS!$C$2:$C$1002=$A7)* (GIRIS_CIKIS!$D$2:$D$1002=$B7)* (GIRIS_CIKIS!$E$2:$E$1002="YESIL"), GIRIS_CIKIS!$F$2:$F$1002 ) ) - SUM( IF( (GIRIS_CIKIS!$B$2:$B$1002="CIKIS")* (GIRIS_CIKIS!$C$2:$C$1002=$A7)* (GIRIS_CIKIS!$D$2:$D$1002=$B7)* (GIRIS_CIKIS!$E$2:$E$1002="YESIL"), GIRIS_CIKIS!$F$2:$F$1002 ) ),0)} -> 1 | E7: {=IFERROR( SUM( IF( (GIRIS_CIKIS!$B$2:$B$1002="GIRIS")* (GIRIS_CIKIS!$C$2:$C$1002=$A7)* (GIRIS_CIKIS!$D$2:$D$1002=$B7)* (GIRIS_CIKIS!$E$2:$E$1002="MOR"), GIRIS_CIKIS!$F$2:$F$1002 ) ) - SUM( IF( (GIRIS_CIKIS!$B$2:$B$1002="CIKIS")* (GIRIS_CIKIS!$C$2:$C$1002=$A7)* (GIRIS_CIKIS!$D$2:$D$1002=$B7)* (GIRIS_CIKIS!$E$2:$E$1002="MOR"), GIRIS_CIKIS!$F$2:$F$1002 ) ),0)} -> 4 | F7: {=IFERROR( SUM( IF( (GIRIS_CIKIS!$B$2:$B$1002="GIRIS")* (GIRIS_CIKIS!$C$2:$C$1002=$A7)* (GIRIS_CIKIS!$D$2:$D$1002=$B7)* (GIRIS_CIKIS!$E$2:$E$1002="ACIK SARI"), GIRIS_CIKIS!$F$2:$F$1002 ) ) - SUM( IF( (GIRIS_CIKIS!$B$2:$B$1002="CIKIS")* (GIRIS_CIKIS!$C$2:$C$1002=$A7)* (GIRIS_CIKIS!$D$2:$D$1002=$B7)* (GIRIS_CIKIS!$E$2:$E$1002="ACIK SARI"), GIRIS_CIKIS!$F$2:$F$1002 ) ),0)} -> 0 | G7: {=IFERROR( SUM( IF( (GIRIS_CIKIS!$B$2:$B$1002="GIRIS")* (GIRIS_CIKIS!$C$2:$C$1002=$A7)* (GIRIS_CIKIS!$D$2:$D$1002=$B7)* (GIRIS_CIKIS!$E$2:$E$1002="SARI"), GIRIS_CIKIS!$F$2:$F$1002 ) ) - SUM( IF( (GIRIS_CIKIS!$B$2:$B$1002="CIKIS")* (GIRIS_CIKIS!$C$2:$C$1002=$A7)* (GIRIS_CIKIS!$D$2:$D$1002=$B7)* (GIRIS_CIKIS!$E$2:$E$1002="SARI"), GIRIS_CIKIS!$F$2:$F$1002 ) ),0)} -> 2 | H7: {=IFERROR( SUM( IF( (GIRIS_CIKIS!$B$2:$B$1002="GIRIS")* (GIRIS_CIKIS!$C$2:$C$1002=$A7)* (GIRIS_CIKIS!$D$2:$D$1002=$B7)* (GIRIS_CIKIS!$E$2:$E$1002="TURUNCU"), GIRIS_CIKIS!$F$2:$F$1002 ) ) - SUM( IF( (GIRIS_CIKIS!$B$2:$B$1002="CIKIS")* (GIRIS_CIKIS!$C$2:$C$1002=$A7)* (GIRIS_CIKIS!$D$2:$D$1002=$B7)* (GIRIS_CIKIS!$E$2:$E$1002="TURUNCU"), GIRIS_CIKIS!$F$2:$F$1002 ) ),0)} -> 2 | I7: {=IFERROR( SUM( IF( (GIRIS_CIKIS!$B$2:$B$1002="GIRIS")* (GIRIS_CIKIS!$C$2:$C$1002=$A7)* (GIRIS_CIKIS!$D$2:$D$1002=$B7)* (GIRIS_CIKIS!$E$2:$E$1002="KIRMIZI"), GIRIS_CIKIS!$F$2:$F$1002 ) ) - SUM( IF( (GIRIS_CIKIS!$B$2:$B$1002="CIKIS")* (GIRIS_CIKIS!$C$2:$C$1002=$A7)* (GIRIS_CIKIS!$D$2:$D$1002=$B7)* (GIRIS_CIKIS!$E$2:$E$1002="KIRMIZI"), GIRIS_CIKIS!$F$2:$F$1002 ) ),0)} -> 0 | J7: {=IFERROR( SUM( IF( (GIRIS_CIKIS!$B$2:$B$1002="GIRIS")* (GIRIS_CIKIS!$C$2:$C$1002=$A7)* (GIRIS_CIKIS!$D$2:$D$1002=$B7)* (GIRIS_CIKIS!$E$2:$E$1002="KAHVERENGI"), GIRIS_CIKIS!$F$2:$F$1002 ) ) - SUM( IF( (GIRIS_CIKIS!$B$2:$B$1002="CIKIS")* (GIRIS_CIKIS!$C$2:$C$1002=$A7)* (GIRIS_CIKIS!$D$2:$D$1002=$B7)* (GIRIS_CIKIS!$E$2:$E$1002="KAHVERENGI"), GIRIS_CIKIS!$F$2:$F$1002 ) ),0)} -> 0 | K7: {=IFERROR( SUM( IF( (GIRIS_CIKIS!$B$2:$B$1002="GIRIS")* (GIRIS_CIKIS!$C$2:$C$1002=$A7)* (GIRIS_CIKIS!$D$2:$D$1002=$B7)* (GIRIS_CIKIS!$E$2:$E$1002="ACIK MOR"), GIRIS_CIKIS!$F$2:$F$1002 ) ) - SUM( IF( (GIRIS_CIKIS!$B$2:$B$1002="CIKIS")* (GIRIS_CIKIS!$C$2:$C$1002=$A7)* (GIRIS_CIKIS!$D$2:$D$1002=$B7)* (GIRIS_CIKIS!$E$2:$E$1002="ACIK MOR"), GIRIS_CIKIS!$F$2:$F$1002 ) ),0)} -> 0 | L7: {=IFERROR( SUM( IF( (GIRIS_CIKIS!$B$2:$B$1002="GIRIS")* (GIRIS_CIKIS!$C$2:$C$1002=$A7)* (GIRIS_CIKIS!$D$2:$D$1002=$B7)* (GIRIS_CIKIS!$E$2:$E$1002="GRI"), GIRIS_CIKIS!$F$2:$F$1002 ) ) - SUM( IF( (GIRIS_CIKIS!$B$2:$B$1002="CIKIS")* (GIRIS_CIKIS!$C$2:$C$1002=$A7)* (GIRIS_CIKIS!$D$2:$D$1002=$B7)* (GIRIS_CIKIS!$E$2:$E$1002="GRI"), GIRIS_CIKIS!$F$2:$F$1002 ) ),0)} -> 0 | M7: {=IFERROR( SUM( IF( (GIRIS_CIKIS!$B$2:$B$1002="GIRIS")* (GIRIS_CIKIS!$C$2:$C$1002=$A7)* (GIRIS_CIKIS!$D$2:$D$1002=$B7)* (GIRIS_CIKIS!$E$2:$E$1002="TURKUAZ"), GIRIS_CIKIS!$F$2:$F$1002 ) ) - SUM( IF( (GIRIS_CIKIS!$B$2:$B$1002="CIKIS")* (GIRIS_CIKIS!$C$2:$C$1002=$A7)* (GIRIS_CIKIS!$D$2:$D$1002=$B7)* (GIRIS_CIKIS!$E$2:$E$1002="TURKUAZ"), GIRIS_CIKIS!$F$2:$F$1002 ) ),0)} -> 0 | N7: {=IFERROR( SUM( IF( (GIRIS_CIKIS!$B$2:$B$1002="GIRIS")* (GIRIS_CIKIS!$C$2:$C$1002=$A7)* (GIRIS_CIKIS!$D$2:$D$1002=$B7)* (GIRIS_CIKIS!$E$2:$E$1002="SIYAH"), GIRIS_CIKIS!$F$2:$F$1002 ) ) - SUM( IF( (GIRIS_CIKIS!$B$2:$B$1002="CIKIS")* (GIRIS_CIKIS!$C$2:$C$1002=$A7)* (GIRIS_CIKIS!$D$2:$D$1002=$B7)* (GIRIS_CIKIS!$E$2:$E$1002="SIYAH"), GIRIS_CIKIS!$F$2:$F$1002 ) ),0)} -> 0 | O7: {=IFERROR( SUM( IF( (GIRIS_CIKIS!$B$2:$B$1002="GIRIS")* (GIRIS_CIKIS!$C$2:$C$1002=$A7)* (GIRIS_CIKIS!$D$2:$D$1002=$B7)* (GIRIS_CIKIS!$E$2:$E$1002="MAVI"), GIRIS_CIKIS!$F$2:$F$1002 ) ) - SUM( IF( (GIRIS_CIKIS!$B$2:$B$1002="CIKIS")* (GIRIS_CIKIS!$C$2:$C$1002=$A7)* (GIRIS_CIKIS!$D$2:$D$1002=$B7)* (GIRIS_CIKIS!$E$2:$E$1002="MAVI"), GIRIS_CIKIS!$F$2:$F$1002 ) ),0)} -> 0 | P7: =SUM(C7:O7) -> 9 | Q7: ADET
A8: MERIDA | B8: H:150CM DUZ DALGALI KAYDIRAK | C8: {=IFERROR( SUM( IF( (GIRIS_CIKIS!$B$2:$B$1002="GIRIS")* (GIRIS_CIKIS!$C$2:$C$1002=$A8)* (GIRIS_CIKIS!$D$2:$D$1002=$B8)* (GIRIS_CIKIS!$E$2:$E$1002="DALDIRMA"), GIRIS_CIKIS!$F$2:$F$1002 ) ) - SUM( IF( (GIRIS_CIKIS!$B$2:$B$1002="CIKIS")* (GIRIS_CIKIS!$C$2:$C$1002=$A8)* (GIRIS_CIKIS!$D$2:$D$1002=$B8)* (GIRIS_CIKIS!$E$2:$E$1002="DALDIRMA"), GIRIS_CIKIS!$F$2:$F$1002 ) ),0)} -> 0 | D8: {=IFERROR( SUM( IF( (GIRIS_CIKIS!$B$2:$B$1002="GIRIS")* (GIRIS_CIKIS!$C$2:$C$1002=$A8)* (GIRIS_CIKIS!$D$2:$D$1002=$B8)* (GIRIS_CIKIS!$E$2:$E$1002="YESIL"), GIRIS_CIKIS!$F$2:$F$1002 ) ) - SUM( IF( (GIRIS_CIKIS!$B$2:$B$1002="CIKIS")* (GIRIS_CIKIS!$C$2:$C$1002=$A8)* (GIRIS_CIKIS!$D$2:$D$1002=$B8)* (GIRIS_CIKIS!$E$2:$E$1002="YESIL"), GIRIS_CIKIS!$F$2:$F$1002 ) ),0)} -> 7 | E8: {=IFERROR( SUM( IF( (GIRIS_CIKIS!$B$2:$B$1002="GIRIS")* (GIRIS_CIKIS!$C$2:$C$1002=$A8)* (GIRIS_CIKIS!$D$2:$D$1002=$B8)* (GIRIS_CIKIS!$E$2:$E$1002="MOR"), GIRIS_CIKIS!$F$2:$F$1002 ) ) - SUM( IF( (GIRIS_CIKIS!$B$2:$B$1002="CIKIS")* (GIRIS_CIKIS!$C$2:$C$1002=$A8)* (GIRIS_CIKIS!$D$2:$D$1002=$B8)* (GIRIS_CIKIS!$E$2:$E$1002="MOR"), GIRIS_CIKIS!$F$2:$F$1002 ) ),0)} -> 1 | F8: {=IFERROR( SUM( IF( (GIRIS_CIKIS!$B$2:$B$1002="GIRIS")* (GIRIS_CIKIS!$C$2:$C$1002=$A8)* (GIRIS_CIKIS!$D$2:$D$1002=$B8)* (GIRIS_CIKIS!$E$2:$E$1002="ACIK SARI"), GIRIS_CIKIS!$F$2:$F$1002 ) ) - SUM( IF( (GIRIS_CIKIS!$B$2:$B$1002="CIKIS")* (GIRIS_CIKIS!$C$2:$C$1002=$A8)* (GIRIS_CIKIS!$D$2:$D$1002=$B8)* (GIRIS_CIKIS!$E$2:$E$1002="ACIK SARI"), GIRIS_CIKIS!$F$2:$F$1002 ) ),0)} -> 0 | G8: {=IFERROR( SUM( IF( (GIRIS_CIKIS!$B$2:$B$1002="GIRIS")* (GIRIS_CIKIS!$C$2:$C$1002=$A8)* (GIRIS_CIKIS!$D$2:$D$1002=$B8)* (GIRIS_CIKIS!$E$2:$E$1002="SARI"), GIRIS_CIKIS!$F$2:$F$1002 ) ) - SUM( IF( (GIRIS_CIKIS!$B$2:$B$1002="CIKIS")* (GIRIS_CIKIS!$C$2:$C$1002=$A8)* (GIRIS_CIKIS!$D$2:$D$1002=$B8)* (GIRIS_CIKIS!$E$2:$E$1002="SARI"), GIRIS_CIKIS!$F$2:$F$1002 ) ),0)} -> 3 | H8: {=IFERROR( SUM( IF( (GIRIS_CIKIS!$B$2:$B$1002="GIRIS")* (GIRIS_CIKIS!$C$2:$C$1002=$A8)* (GIRIS_CIKIS!$D$2:$D$1002=$B8)* (GIRIS_CIKIS!$E$2:$E$1002="TURUNCU"), GIRIS_CIKIS!$F$2:$F$1002 ) ) - SUM( IF( (GIRIS_CIKIS!$B$2:$B$1002="CIKIS")* (GIRIS_CIKIS!$C$2:$C$1002=$A8)* (GIRIS_CIKIS!$D$2:$D$1002=$B8)* (GIRIS_CIKIS!$E$2:$E$1002="TURUNCU"), GIRIS_CIKIS!$F$2:$F$1002 ) ),0)} -> 1 | I8: {=IFERROR( SUM( IF( (GIRIS_CIKIS!$B$2:$B$1002="GIRIS")* (GIRIS_CIKIS!$C$2:$C$1002=$A8)* (GIRIS_CIKIS!$D$2:$D$1002=$B8)* (GIRIS_CIKIS!$E$2:$E$1002="KIRMIZI"), GIRIS_CIKIS!$F$2:$F$1002 ) ) - SUM( IF( (GIRIS_CIKIS!$B$2:$B$1002="CIKIS")* (GIRIS_CIKIS!$C$2:$C$1002=$A8)* (GIRIS_CIKIS!$D$2:$D$1002=$B8)* (GIRIS_CIKIS!$E$2:$E$1002="KIRMIZI"), GIRIS_CIKIS!$F$2:$F$1002 ) ),0)} -> 0 | J8: {=IFERROR( SUM( IF( (GIRIS_CIKIS!$B$2:$B$1002="GIRIS")* (GIRIS_CIKIS!$C$2:$C$1002=$A8)* (GIRIS_CIKIS!$D$2:$D$1002=$B8)* (GIRIS_CIKIS!$E$2:$E$1002="KAHVERENGI"), GIRIS_CIKIS!$F$2:$F$1002 ) ) - SUM( IF( (GIRIS_CIKIS!$B$2:$B$1002="CIKIS")* (GIRIS_CIKIS!$C$2:$C$1002=$A8)* (GIRIS_CIKIS!$D$2:$D$1002=$B8)* (GIRIS_CIKIS!$E$2:$E$1002="KAHVERENGI"), GIRIS_CIKIS!$F$2:$F$1002 ) ),0)} -> 0 | K8: {=IFERROR( SUM( IF( (GIRIS_CIKIS!$B$2:$B$1002="GIRIS")* (GIRIS_CIKIS!$C$2:$C$1002=$A8)* (GIRIS_CIKIS!$D$2:$D$1002=$B8)* (GIRIS_CIKIS!$E$2:$E$1002="ACIK MOR"), GIRIS_CIKIS!$F$2:$F$1002 ) ) - SUM( IF( (GIRIS_CIKIS!$B$2:$B$1002="CIKIS")* (GIRIS_CIKIS!$C$2:$C$1002=$A8)* (GIRIS_CIKIS!$D$2:$D$1002=$B8)* (GIRIS_CIKIS!$E$2:$E$1002="ACIK MOR"), GIRIS_CIKIS!$F$2:$F$1002 ) ),0)} -> 0 | L8: {=IFERROR( SUM( IF( (GIRIS_CIKIS!$B$2:$B$1002="GIRIS")* (GIRIS_CIKIS!$C$2:$C$1002=$A8)* (GIRIS_CIKIS!$D$2:$D$1002=$B8)* (GIRIS_CIKIS!$E$2:$E$1002="GRI"), GIRIS_CIKIS!$F$2:$F$1002 ) ) - SUM( IF( (GIRIS_CIKIS!$B$2:$B$1002="CIKIS")* (GIRIS_CIKIS!$C$2:$C$1002=$A8)* (GIRIS_CIKIS!$D$2:$D$1002=$B8)* (GIRIS_CIKIS!$E$2:$E$1002="GRI"), GIRIS_CIKIS!$F$2:$F$1002 ) ),0)} -> 0 | M8: {=IFERROR( SUM( IF( (GIRIS_CIKIS!$B$2:$B$1002="GIRIS")* (GIRIS_CIKIS!$C$2:$C$1002=$A8)* (GIRIS_CIKIS!$D$2:$D$1002=$B8)* (GIRIS_CIKIS!$E$2:$E$1002="TURKUAZ"), GIRIS_CIKIS!$F$2:$F$1002 ) ) - SUM( IF( (GIRIS_CIKIS!$B$2:$B$1002="CIKIS")* (GIRIS_CIKIS!$C$2:$C$1002=$A8)* (GIRIS_CIKIS!$D$2:$D$1002=$B8)* (GIRIS_CIKIS!$E$2:$E$1002="TURKUAZ"), GIRIS_CIKIS!$F$2:$F$1002 ) ),0)} -> 0 | N8: {=IFERROR( SUM( IF( (GIRIS_CIKIS!$B$2:$B$1002="GIRIS")* (GIRIS_CIKIS!$C$2:$C$1002=$A8)* (GIRIS_CIKIS!$D$2:$D$1002=$B8)* (GIRIS_CIKIS!$E$2:$E$1002="SIYAH"), GIRIS_CIKIS!$F$2:$F$1002 ) ) - SUM( IF( (GIRIS_CIKIS!$B$2:$B$1002="CIKIS")* (GIRIS_CIKIS!$C$2:$C$1002=$A8)* (GIRIS_CIKIS!$D$2:$D$1002=$B8)* (GIRIS_CIKIS!$E$2:$E$1002="SIYAH"), GIRIS_CIKIS!$F$2:$F$1002 ) ),0)} -> 0 | O8: {=IFERROR( SUM( IF( (GIRIS_CIKIS!$B$2:$B$1002="GIRIS")* (GIRIS_CIKIS!$C$2:$C$1002=$A8)* (GIRIS_CIKIS!$D$2:$D$1002=$B8)* (GIRIS_CIKIS!$E$2:$E$1002="MAVI"), GIRIS_CIKIS!$F$2:$F$1002 ) ) - SUM( IF( (GIRIS_CIKIS!$B$2:$B$1002="CIKIS")* (GIRIS_CIKIS!$C$2:$C$1002=$A8)* (GIRIS_CIKIS!$D$2:$D$1002=$B8)* (GIRIS_CIKIS!$E$2:$E$1002="MAVI"), GIRIS_CIKIS!$F$2:$F$1002 ) ),0)} -> 0 | P8: =SUM(C8:O8) -> 12 | Q8: ADET
A9: ROTA | B9: H:200CM SPIRAL KAYDIRAK | C9: {=IFERROR( SUM( IF( (GIRIS_CIKIS!$B$2:$B$1002="GIRIS")* (GIRIS_CIKIS!$C$2:$C$1002=$A9)* (GIRIS_CIKIS!$D$2:$D$1002=$B9)* (GIRIS_CIKIS!$E$2:$E$1002="DALDIRMA"), GIRIS_CIKIS!$F$2:$F$1002 ) ) - SUM( IF( (GIRIS_CIKIS!$B$2:$B$1002="CIKIS")* (GIRIS_CIKIS!$C$2:$C$1002=$A9)* (GIRIS_CIKIS!$D$2:$D$1002=$B9)* (GIRIS_CIKIS!$E$2:$E$1002="DALDIRMA"), GIRIS_CIKIS!$F$2:$F$1002 ) ),0)} -> 0 | D9: {=IFERROR( SUM( IF( (GIRIS_CIKIS!$B$2:$B$1002="GIRIS")* (GIRIS_CIKIS!$C$2:$C$1002=$A9)* (GIRIS_CIKIS!$D$2:$D$1002=$B9)* (GIRIS_CIKIS!$E$2:$E$1002="YESIL"), GIRIS_CIKIS!$F$2:$F$1002 ) ) - SUM( IF( (GIRIS_CIKIS!$B$2:$B$1002="CIKIS")* (GIRIS_CIKIS!$C$2:$C$1002=$A9)* (GIRIS_CIKIS!$D$2:$D$1002=$B9)* (GIRIS_CIKIS!$E$2:$E$1002="YESIL"), GIRIS_CIKIS!$F$2:$F$1002 ) ),0)} -> 0 | E9: {=IFERROR( SUM( IF( (GIRIS_CIKIS!$B$2:$B$1002="GIRIS")* (GIRIS_CIKIS!$C$2:$C$1002=$A9)* (GIRIS_CIKIS!$D$2:$D$1002=$B9)* (GIRIS_CIKIS!$E$2:$E$1002="MOR"), GIRIS_CIKIS!$F$2:$F$1002 ) ) - SUM( IF( (GIRIS_CIKIS!$B$2:$B$1002="CIKIS")* (GIRIS_CIKIS!$C$2:$C$1002=$A9)* (GIRIS_CIKIS!$D$2:$D$1002=$B9)* (GIRIS_CIKIS!$E$2:$E$1002="MOR"), GIRIS_CIKIS!$F$2:$F$1002 ) ),0)} -> 1 | F9: {=IFERROR( SUM( IF( (GIRIS_CIKIS!$B$2:$B$1002="GIRIS")* (GIRIS_CIKIS!$C$2:$C$1002=$A9)* (GIRIS_CIKIS!$D$2:$D$1002=$B9)* (GIRIS_CIKIS!$E$2:$E$1002="ACIK SARI"), GIRIS_CIKIS!$F$2:$F$1002 ) ) - SUM( IF( (GIRIS_CIKIS!$B$2:$B$1002="CIKIS")* (GIRIS_CIKIS!$C$2:$C$1002=$A9)* (GIRIS_CIKIS!$D$2:$D$1002=$B9)* (GIRIS_CIKIS!$E$2:$E$1002="ACIK SARI"), GIRIS_CIKIS!$F$2:$F$1002 ) ),0)} -> 0 | G9: {=IFERROR( SUM( IF( (GIRIS_CIKIS!$B$2:$B$1002="GIRIS")* (GIRIS_CIKIS!$C$2:$C$1002=$A9)* (GIRIS_CIKIS!$D$2:$D$1002=$B9)* (GIRIS_CIKIS!$E$2:$E$1002="SARI"), GIRIS_CIKIS!$F$2:$F$1002 ) ) - SUM( IF( (GIRIS_CIKIS!$B$2:$B$1002="CIKIS")* (GIRIS_CIKIS!$C$2:$C$1002=$A9)* (GIRIS_CIKIS!$D$2:$D$1002=$B9)* (GIRIS_CIKIS!$E$2:$E$1002="SARI"), GIRIS_CIKIS!$F$2:$F$1002 ) ),0)} -> 4 | H9: {=IFERROR( SUM( IF( (GIRIS_CIKIS!$B$2:$B$1002="GIRIS")* (GIRIS_CIKIS!$C$2:$C$1002=$A9)* (GIRIS_CIKIS!$D$2:$D$1002=$B9)* (GIRIS_CIKIS!$E$2:$E$1002="TURUNCU"), GIRIS_CIKIS!$F$2:$F$1002 ) ) - SUM( IF( (GIRIS_CIKIS!$B$2:$B$1002="CIKIS")* (GIRIS_CIKIS!$C$2:$C$1002=$A9)* (GIRIS_CIKIS!$D$2:$D$1002=$B9)* (GIRIS_CIKIS!$E$2:$E$1002="TURUNCU"), GIRIS_CIKIS!$F$2:$F$1002 ) ),0)} -> 0 | I9: {=IFERROR( SUM( IF( (GIRIS_CIKIS!$B$2:$B$1002="GIRIS")* (GIRIS_CIKIS!$C$2:$C$1002=$A9)* (GIRIS_CIKIS!$D$2:$D$1002=$B9)* (GIRIS_CIKIS!$E$2:$E$1002="KIRMIZI"), GIRIS_CIKIS!$F$2:$F$1002 ) ) - SUM( IF( (GIRIS_CIKIS!$B$2:$B$1002="CIKIS")* (GIRIS_CIKIS!$C$2:$C$1002=$A9)* (GIRIS_CIKIS!$D$2:$D$1002=$B9)* (GIRIS_CIKIS!$E$2:$E$1002="KIRMIZI"), GIRIS_CIKIS!$F$2:$F$1002 ) ),0)} -> 0 | J9: {=IFERROR( SUM( IF( (GIRIS_CIKIS!$B$2:$B$1002="GIRIS")* (GIRIS_CIKIS!$C$2:$C$1002=$A9)* (GIRIS_CIKIS!$D$2:$D$1002=$B9)* (GIRIS_CIKIS!$E$2:$E$1002="KAHVERENGI"), GIRIS_CIKIS!$F$2:$F$1002 ) ) - SUM( IF( (GIRIS_CIKIS!$B$2:$B$1002="CIKIS")* (GIRIS_CIKIS!$C$2:$C$1002=$A9)* (GIRIS_CIKIS!$D$2:$D$1002=$B9)* (GIRIS_CIKIS!$E$2:$E$1002="KAHVERENGI"), GIRIS_CIKIS!$F$2:$F$1002 ) ),0)} -> 0 | K9: {=IFERROR( SUM( IF( (GIRIS_CIKIS!$B$2:$B$1002="GIRIS")* (GIRIS_CIKIS!$C$2:$C$1002=$A9)* (GIRIS_CIKIS!$D$2:$D$1002=$B9)* (GIRIS_CIKIS!$E$2:$E$1002="ACIK MOR"), GIRIS_CIKIS!$F$2:$F$1002 ) ) - SUM( IF( (GIRIS_CIKIS!$B$2:$B$1002="CIKIS")* (GIRIS_CIKIS!$C$2:$C$1002=$A9)* (GIRIS_CIKIS!$D$2:$D$1002=$B9)* (GIRIS_CIKIS!$E$2:$E$1002="ACIK MOR"), GIRIS_CIKIS!$F$2:$F$1002 ) ),0)} -> 0 | L9: {=IFERROR( SUM( IF( (GIRIS_CIKIS!$B$2:$B$1002="GIRIS")* (GIRIS_CIKIS!$C$2:$C$1002=$A9)* (GIRIS_CIKIS!$D$2:$D$1002=$B9)* (GIRIS_CIKIS!$E$2:$E$1002="GRI"), GIRIS_CIKIS!$F$2:$F$1002 ) ) - SUM( IF( (GIRIS_CIKIS!$B$2:$B$1002="CIKIS")* (GIRIS_CIKIS!$C$2:$C$1002=$A9)* (GIRIS_CIKIS!$D$2:$D$1002=$B9)* (GIRIS_CIKIS!$E$2:$E$1002="GRI"), GIRIS_CIKIS!$F$2:$F$1002 ) ),0)} -> 0 | M9: {=IFERROR( SUM( IF( (GIRIS_CIKIS!$B$2:$B$1002="GIRIS")* (GIRIS_CIKIS!$C$2:$C$1002=$A9)* (GIRIS_CIKIS!$D$2:$D$1002=$B9)* (GIRIS_CIKIS!$E$2:$E$1002="TURKUAZ"), GIRIS_CIKIS!$F$2:$F$1002 ) ) - SUM( IF( (GIRIS_CIKIS!$B$2:$B$1002="CIKIS")* (GIRIS_CIKIS!$C$2:$C$1002=$A9)* (GIRIS_CIKIS!$D$2:$D$1002=$B9)* (GIRIS_CIKIS!$E$2:$E$1002="TURKUAZ"), GIRIS_CIKIS!$F$2:$F$1002 ) ),0)} -> 0 | N9: {=IFERROR( SUM( IF( (GIRIS_CIKIS!$B$2:$B$1002="GIRIS")* (GIRIS_CIKIS!$C$2:$C$1002=$A9)* (GIRIS_CIKIS!$D$2:$D$1002=$B9)* (GIRIS_CIKIS!$E$2:$E$1002="SIYAH"), GIRIS_CIKIS!$F$2:$F$1002 ) ) - SUM( IF( (GIRIS_CIKIS!$B$2:$B$1002="CIKIS")* (GIRIS_CIKIS!$C$2:$C$1002=$A9)* (GIRIS_CIKIS!$D$2:$D$1002=$B9)* (GIRIS_CIKIS!$E$2:$E$1002="SIYAH"), GIRIS_CIKIS!$F$2:$F$1002 ) ),0)} -> 0 | O9: {=IFERROR( SUM( IF( (GIRIS_CIKIS!$B$2:$B$1002="GIRIS")* (GIRIS_CIKIS!$C$2:$C$1002=$A9)* (GIRIS_CIKIS!$D$2:$D$1002=$B9)* (GIRIS_CIKIS!$E$2:$E$1002="MAVI"), GIRIS_CIKIS!$F$2:$F$1002 ) ) - SUM( IF( (GIRIS_CIKIS!$B$2:$B$1002="CIKIS")* (GIRIS_CIKIS!$C$2:$C$1002=$A9)* (GIRIS_CIKIS!$D$2:$D$1002=$B9)* (GIRIS_CIKIS!$E$2:$E$1002="MAVI"), GIRIS_CIKIS!$F$2:$F$1002 ) ),0)} -> 0 | P9: =SUM(C9:O9) -> 5 | Q9: ADET
A10: KOCAKPARK | B10: H:200CM SPIRAL KAYDIRAK | C10: {=IFERROR( SUM( IF( (GIRIS_CIKIS!$B$2:$B$1002="GIRIS")* (GIRIS_CIKIS!$C$2:$C$1002=$A10)* (GIRIS_CIKIS!$D$2:$D$1002=$B10)* (GIRIS_CIKIS!$E$2:$E$1002="DALDIRMA"), GIRIS_CIKIS!$F$2:$F$1002 ) ) - SUM( IF( (GIRIS_CIKIS!$B$2:$B$1002="CIKIS")* (GIRIS_CIKIS!$C$2:$C$1002=$A10)* (GIRIS_CIKIS!$D$2:$D$1002=$B10)* (GIRIS_CIKIS!$E$2:$E$1002="DALDIRMA"), GIRIS_CIKIS!$F$2:$F$1002 ) ),0)} -> 0 | D10: {=IFERROR( SUM( IF( (GIRIS_CIKIS!$B$2:$B$1002="GIRIS")* (GIRIS_CIKIS!$C$2:$C$1002=$A10)* (GIRIS_CIKIS!$D$2:$D$1002=$B10)* (GIRIS_CIKIS!$E$2:$E$1002="YESIL"), GIRIS_CIKIS!$F$2:$F$1002 ) ) - SUM( IF( (GIRIS_CIKIS!$B$2:$B$1002="CIKIS")* (GIRIS_CIKIS!$C$2:$C$1002=$A10)* (GIRIS_CIKIS!$D$2:$D$1002=$B10)* (GIRIS_CIKIS!$E$2:$E$1002="YESIL"), GIRIS_CIKIS!$F$2:$F$1002 ) ),0)} -> 4 | E10: {=IFERROR( SUM( IF( (GIRIS_CIKIS!$B$2:$B$1002="GIRIS")* (GIRIS_CIKIS!$C$2:$C$1002=$A10)* (GIRIS_CIKIS!$D$2:$D$1002=$B10)* (GIRIS_CIKIS!$E$2:$E$1002="MOR"), GIRIS_CIKIS!$F$2:$F$1002 ) ) - SUM( IF( (GIRIS_CIKIS!$B$2:$B$1002="CIKIS")* (GIRIS_CIKIS!$C$2:$C$1002=$A10)* (GIRIS_CIKIS!$D$2:$D$1002=$B10)* (GIRIS_CIKIS!$E$2:$E$1002="MOR"), GIRIS_CIKIS!$F$2:$F$1002 ) ),0)} -> 0 | F10: {=IFERROR( SUM( IF( (GIRIS_CIKIS!$B$2:$B$1002="GIRIS")* (GIRIS_CIKIS!$C$2:$C$1002=$A10)* (GIRIS_CIKIS!$D$2:$D$1002=$B10)* (GIRIS_CIKIS!$E$2:$E$1002="ACIK SARI"), GIRIS_CIKIS!$F$2:$F$1002 ) ) - SUM( IF( (GIRIS_CIKIS!$B$2:$B$1002="CIKIS")* (GIRIS_CIKIS!$C$2:$C$1002=$A10)* (GIRIS_CIKIS!$D$2:$D$1002=$B10)* (GIRIS_CIKIS!$E$2:$E$1002="ACIK SARI"), GIRIS_CIKIS!$F$2:$F$1002 ) ),0)} -> 0 | G10: {=IFERROR( SUM( IF( (GIRIS_CIKIS!$B$2:$B$1002="GIRIS")* (GIRIS_CIKIS!$C$2:$C$1002=$A10)* (GIRIS_CIKIS!$D$2:$D$1002=$B10)* (GIRIS_CIKIS!$E$2:$E$1002="SARI"), GIRIS_CIKIS!$F$2:$F$1002 ) ) - SUM( IF( (GIRIS_CIKIS!$B$2:$B$1002="CIKIS")* (GIRIS_CIKIS!$C$2:$C$1002=$A10)* (GIRIS_CIKIS!$D$2:$D$1002=$B10)* (GIRIS_CIKIS!$E$2:$E$1002="SARI"), GIRIS_CIKIS!$F$2:$F$1002 ) ),0)} -> 3 | H10: {=IFERROR( SUM( IF( (GIRIS_CIKIS!$B$2:$B$1002="GIRIS")* (GIRIS_CIKIS!$C$2:$C$1002=$A10)* (GIRIS_CIKIS!$D$2:$D$1002=$B10)* (GIRIS_CIKIS!$E$2:$E$1002="TURUNCU"), GIRIS_CIKIS!$F$2:$F$1002 ) ) - SUM( IF( (GIRIS_CIKIS!$B$2:$B$1002="CIKIS")* (GIRIS_CIKIS!$C$2:$C$1002=$A10)* (GIRIS_CIKIS!$D$2:$D$1002=$B10)* (GIRIS_CIKIS!$E$2:$E$1002="TURUNCU"), GIRIS_CIKIS!$F$2:$F$1002 ) ),0)} -> 3 | I10: {=IFERROR( SUM( IF( (GIRIS_CIKIS!$B$2:$B$1002="GIRIS")* (GIRIS_CIKIS!$C$2:$C$1002=$A10)* (GIRIS_CIKIS!$D$2:$D$1002=$B10)* (GIRIS_CIKIS!$E$2:$E$1002="KIRMIZI"), GIRIS_CIKIS!$F$2:$F$1002 ) ) - SUM( IF( (GIRIS_CIKIS!$B$2:$B$1002="CIKIS")* (GIRIS_CIKIS!$C$2:$C$1002=$A10)* (GIRIS_CIKIS!$D$2:$D$1002=$B10)* (GIRIS_CIKIS!$E$2:$E$1002="KIRMIZI"), GIRIS_CIKIS!$F$2:$F$1002 ) ),0)} -> 0 | J10: {=IFERROR( SUM( IF( (GIRIS_CIKIS!$B$2:$B$1002="GIRIS")* (GIRIS_CIKIS!$C$2:$C$1002=$A10)* (GIRIS_CIKIS!$D$2:$D$1002=$B10)* (GIRIS_CIKIS!$E$2:$E$1002="KAHVERENGI"), GIRIS_CIKIS!$F$2:$F$1002 ) ) - SUM( IF( (GIRIS_CIKIS!$B$2:$B$1002="CIKIS")* (GIRIS_CIKIS!$C$2:$C$1002=$A10)* (GIRIS_CIKIS!$D$2:$D$1002=$B10)* (GIRIS_CIKIS!$E$2:$E$1002="KAHVERENGI"), GIRIS_CIKIS!$F$2:$F$1002 ) ),0)} -> 0 | K10: {=IFERROR( SUM( IF( (GIRIS_CIKIS!$B$2:$B$1002="GIRIS")* (GIRIS_CIKIS!$C$2:$C$1002=$A10)* (GIRIS_CIKIS!$D$2:$D$1002=$B10)* (GIRIS_CIKIS!$E$2:$E$1002="ACIK MOR"), GIRIS_CIKIS!$F$2:$F$1002 ) ) - SUM( IF( (GIRIS_CIKIS!$B$2:$B$1002="CIKIS")* (GIRIS_CIKIS!$C$2:$C$1002=$A10)* (GIRIS_CIKIS!$D$2:$D$1002=$B10)* (GIRIS_CIKIS!$E$2:$E$1002="ACIK MOR"), GIRIS_CIKIS!$F$2:$F$1002 ) ),0)} -> 0 | L10: {=IFERROR( SUM( IF( (GIRIS_CIKIS!$B$2:$B$1002="GIRIS")* (GIRIS_CIKIS!$C$2:$C$1002=$A10)* (GIRIS_CIKIS!$D$2:$D$1002=$B10)* (GIRIS_CIKIS!$E$2:$E$1002="GRI"), GIRIS_CIKIS!$F$2:$F$1002 ) ) - SUM( IF( (GIRIS_CIKIS!$B$2:$B$1002="CIKIS")* (GIRIS_CIKIS!$C$2:$C$1002=$A10)* (GIRIS_CIKIS!$D$2:$D$1002=$B10)* (GIRIS_CIKIS!$E$2:$E$1002="GRI"), GIRIS_CIKIS!$F$2:$F$1002 ) ),0)} -> 0 | M10: {=IFERROR( SUM( IF( (GIRIS_CIKIS!$B$2:$B$1002="GIRIS")* (GIRIS_CIKIS!$C$2:$C$1002=$A10)* (GIRIS_CIKIS!$D$2:$D$1002=$B10)* (GIRIS_CIKIS!$E$2:$E$1002="TURKUAZ"), GIRIS_CIKIS!$F$2:$F$1002 ) ) - SUM( IF( (GIRIS_CIKIS!$B$2:$B$1002="CIKIS")* (GIRIS_CIKIS!$C$2:$C$1002=$A10)* (GIRIS_CIKIS!$D$2:$D$1002=$B10)* (GIRIS_CIKIS!$E$2:$E$1002="TURKUAZ"), GIRIS_CIKIS!$F$2:$F$1002 ) ),0)} -> 0 | N10: {=IFERROR( SUM( IF( (GIRIS_CIKIS!$B$2:$B$1002="GIRIS")* (GIRIS_CIKIS!$C$2:$C$1002=$A10)* (GIRIS_CIKIS!$D$2:$D$1002=$B10)* (GIRIS_CIKIS!$E$2:$E$1002="SIYAH"), GIRIS_CIKIS!$F$2:$F$1002 ) ) - SUM( IF( (GIRIS_CIKIS!$B$2:$B$1002="CIKIS")* (GIRIS_CIKIS!$C$2:$C$1002=$A10)* (GIRIS_CIKIS!$D$2:$D$1002=$B10)* (GIRIS_CIKIS!$E$2:$E$1002="SIYAH"), GIRIS_CIKIS!$F$2:$F$1002 ) ),0)} -> 0 | O10: {=IFERROR( SUM( IF( (GIRIS_CIKIS!$B$2:$B$1002="GIRIS")* (GIRIS_CIKIS!$C$2:$C$1002=$A10)* (GIRIS_CIKIS!$D$2:$D$1002=$B10)* (GIRIS_CIKIS!$E$2:$E$1002="MAVI"), GIRIS_CIKIS!$F$2:$F$1002 ) ) - SUM( IF( (GIRIS_CIKIS!$B$2:$B$1002="CIKIS")* (GIRIS_CIKIS!$C$2:$C$1002=$A10)* (GIRIS_CIKIS!$D$2:$D$1002=$B10)* (GIRIS_CIKIS!$E$2:$E$1002="MAVI"), GIRIS_CIKIS!$F$2:$F$1002 ) ),0)} -> 0 | P10: =SUM(C10:O10) -> 10 | Q10: ADET
A11: MERIDA | B11: H:150CM IKILI DUZ KAYDIRAK | C11: {=IFERROR( SUM( IF( (GIRIS_CIKIS!$B$2:$B$1002="GIRIS")* (GIRIS_CIKIS!$C$2:$C$1002=$A11)* (GIRIS_CIKIS!$D$2:$D$1002=$B11)* (GIRIS_CIKIS!$E$2:$E$1002="DALDIRMA"), GIRIS_CIKIS!$F$2:$F$1002 ) ) - SUM( IF( (GIRIS_CIKIS!$B$2:$B$1002="CIKIS")* (GIRIS_CIKIS!$C$2:$C$1002=$A11)* (GIRIS_CIKIS!$D$2:$D$1002=$B11)* (GIRIS_CIKIS!$E$2:$E$1002="DALDIRMA"), GIRIS_CIKIS!$F$2:$F$1002 ) ),0)} -> 0 | D11: {=IFERROR( SUM( IF( (GIRIS_CIKIS!$B$2:$B$1002="GIRIS")* (GIRIS_CIKIS!$C$2:$C$1002=$A11)* (GIRIS_CIKIS!$D$2:$D$1002=$B11)* (GIRIS_CIKIS!$E$2:$E$1002="YESIL"), GIRIS_CIKIS!$F$2:$F$1002 ) ) - SUM( IF( (GIRIS_CIKIS!$B$2:$B$1002="CIKIS")* (GIRIS_CIKIS!$C$2:$C$1002=$A11)* (GIRIS_CIKIS!$D$2:$D$1002=$B11)* (GIRIS_CIKIS!$E$2:$E$1002="YESIL"), GIRIS_CIKIS!$F$2:$F$1002 ) ),0)} -> 3 | E11: {=IFERROR( SUM( IF( (GIRIS_CIKIS!$B$2:$B$1002="GIRIS")* (GIRIS_CIKIS!$C$2:$C$1002=$A11)* (GIRIS_CIKIS!$D$2:$D$1002=$B11)* (GIRIS_CIKIS!$E$2:$E$1002="MOR"), GIRIS_CIKIS!$F$2:$F$1002 ) ) - SUM( IF( (GIRIS_CIKIS!$B$2:$B$1002="CIKIS")* (GIRIS_CIKIS!$C$2:$C$1002=$A11)* (GIRIS_CIKIS!$D$2:$D$1002=$B11)* (GIRIS_CIKIS!$E$2:$E$1002="MOR"), GIRIS_CIKIS!$F$2:$F$1002 ) ),0)} -> 3 | F11: {=IFERROR( SUM( IF( (GIRIS_CIKIS!$B$2:$B$1002="GIRIS")* (GIRIS_CIKIS!$C$2:$C$1002=$A11)* (GIRIS_CIKIS!$D$2:$D$1002=$B11)* (GIRIS_CIKIS!$E$2:$E$1002="ACIK SARI"), GIRIS_CIKIS!$F$2:$F$1002 ) ) - SUM( IF( (GIRIS_CIKIS!$B$2:$B$1002="CIKIS")* (GIRIS_CIKIS!$C$2:$C$1002=$A11)* (GIRIS_CIKIS!$D$2:$D$1002=$B11)* (GIRIS_CIKIS!$E$2:$E$1002="ACIK SARI"), GIRIS_CIKIS!$F$2:$F$1002 ) ),0)} -> 0 | G11: {=IFERROR( SUM( IF( (GIRIS_CIKIS!$B$2:$B$1002="GIRIS")* (GIRIS_CIKIS!$C$2:$C$1002=$A11)* (GIRIS_CIKIS!$D$2:$D$1002=$B11)* (GIRIS_CIKIS!$E$2:$E$1002="SARI"), GIRIS_CIKIS!$F$2:$F$1002 ) ) - SUM( IF( (GIRIS_CIKIS!$B$2:$B$1002="CIKIS")* (GIRIS_CIKIS!$C$2:$C$1002=$A11)* (GIRIS_CIKIS!$D$2:$D$1002=$B11)* (GIRIS_CIKIS!$E$2:$E$1002="SARI"), GIRIS_CIKIS!$F$2:$F$1002 ) ),0)} -> 5 | H11: {=IFERROR( SUM( IF( (GIRIS_CIKIS!$B$2:$B$1002="GIRIS")* (GIRIS_CIKIS!$C$2:$C$1002=$A11)* (GIRIS_CIKIS!$D$2:$D$1002=$B11)* (GIRIS_CIKIS!$E$2:$E$1002="TURUNCU"), GIRIS_CIKIS!$F$2:$F$1002 ) ) - SUM( IF( (GIRIS_CIKIS!$B$2:$B$1002="CIKIS")* (GIRIS_CIKIS!$C$2:$C$1002=$A11)* (GIRIS_CIKIS!$D$2:$D$1002=$B11)* (GIRIS_CIKIS!$E$2:$E$1002="TURUNCU"), GIRIS_CIKIS!$F$2:$F$1002 ) ),0)} -> 1 | I11: {=IFERROR( SUM( IF( (GIRIS_CIKIS!$B$2:$B$1002="GIRIS")* (GIRIS_CIKIS!$C$2:$C$1002=$A11)* (GIRIS_CIKIS!$D$2:$D$1002=$B11)* (GIRIS_CIKIS!$E$2:$E$1002="KIRMIZI"), GIRIS_CIKIS!$F$2:$F$1002 ) ) - SUM( IF( (GIRIS_CIKIS!$B$2:$B$1002="CIKIS")* (GIRIS_CIKIS!$C$2:$C$1002=$A11)* (GIRIS_CIKIS!$D$2:$D$1002=$B11)* (GIRIS_CIKIS!$E$2:$E$1002="KIRMIZI"), GIRIS_CIKIS!$F$2:$F$1002 ) ),0)} -> 0 | J11: {=IFERROR( SUM( IF( (GIRIS_CIKIS!$B$2:$B$1002="GIRIS")* (GIRIS_CIKIS!$C$2:$C$1002=$A11)* (GIRIS_CIKIS!$D$2:$D$1002=$B11)* (GIRIS_CIKIS!$E$2:$E$1002="KAHVERENGI"), GIRIS_CIKIS!$F$2:$F$1002 ) ) - SUM( IF( (GIRIS_CIKIS!$B$2:$B$1002="CIKIS")* (GIRIS_CIKIS!$C$2:$C$1002=$A11)* (GIRIS_CIKIS!$D$2:$D$1002=$B11)* (GIRIS_CIKIS!$E$2:$E$1002="KAHVERENGI"), GIRIS_CIKIS!$F$2:$F$1002 ) ),0)} -> 0 | K11: {=IFERROR( SUM( IF( (GIRIS_CIKIS!$B$2:$B$1002="GIRIS")* (GIRIS_CIKIS!$C$2:$C$1002=$A11)* (GIRIS_CIKIS!$D$2:$D$1002=$B11)* (GIRIS_CIKIS!$E$2:$E$1002="ACIK MOR"), GIRIS_CIKIS!$F$2:$F$1002 ) ) - SUM( IF( (GIRIS_CIKIS!$B$2:$B$1002="CIKIS")* (GIRIS_CIKIS!$C$2:$C$1002=$A11)* (GIRIS_CIKIS!$D$2:$D$1002=$B11)* (GIRIS_CIKIS!$E$2:$E$1002="ACIK MOR"), GIRIS_CIKIS!$F$2:$F$1002 ) ),0)} -> 0 | L11: {=IFERROR( SUM( IF( (GIRIS_CIKIS!$B$2:$B$1002="GIRIS")* (GIRIS_CIKIS!$C$2:$C$1002=$A11)* (GIRIS_CIKIS!$D$2:$D$1002=$B11)* (GIRIS_CIKIS!$E$2:$E$1002="GRI"), GIRIS_CIKIS!$F$2:$F$1002 ) ) - SUM( IF( (GIRIS_CIKIS!$B$2:$B$1002="CIKIS")* (GIRIS_CIKIS!$C$2:$C$1002=$A11)* (GIRIS_CIKIS!$D$2:$D$1002=$B11)* (GIRIS_CIKIS!$E$2:$E$1002="GRI"), GIRIS_CIKIS!$F$2:$F$1002 ) ),0)} -> 0 | M11: {=IFERROR( SUM( IF( (GIRIS_CIKIS!$B$2:$B$1002="GIRIS")* (GIRIS_CIKIS!$C$2:$C$1002=$A11)* (GIRIS_CIKIS!$D$2:$D$1002=$B11)* (GIRIS_CIKIS!$E$2:$E$1002="TURKUAZ"), GIRIS_CIKIS!$F$2:$F$1002 ) ) - SUM( IF( (GIRIS_CIKIS!$B$2:$B$1002="CIKIS")* (GIRIS_CIKIS!$C$2:$C$1002=$A11)* (GIRIS_CIKIS!$D$2:$D$1002=$B11)* (GIRIS_CIKIS!$E$2:$E$1002="TURKUAZ"), GIRIS_CIKIS!$F$2:$F$1002 ) ),0)} -> 0 | N11: {=IFERROR( SUM( IF( (GIRIS_CIKIS!$B$2:$B$1002="GIRIS")* (GIRIS_CIKIS!$C$2:$C$1002=$A11)* (GIRIS_CIKIS!$D$2:$D$1002=$B11)* (GIRIS_CIKIS!$E$2:$E$1002="SIYAH"), GIRIS_CIKIS!$F$2:$F$1002 ) ) - SUM( IF( (GIRIS_CIKIS!$B$2:$B$1002="CIKIS")* (GIRIS_CIKIS!$C$2:$C$1002=$A11)* (GIRIS_CIKIS!$D$2:$D$1002=$B11)* (GIRIS_CIKIS!$E$2:$E$1002="SIYAH"), GIRIS_CIKIS!$F$2:$F$1002 ) ),0)} -> 0 | O11: {=IFERROR( SUM( IF( (GIRIS_CIKIS!$B$2:$B$1002="GIRIS")* (GIRIS_CIKIS!$C$2:$C$1002=$A11)* (GIRIS_CIKIS!$D$2:$D$1002=$B11)* (GIRIS_CIKIS!$E$2:$E$1002="MAVI"), GIRIS_CIKIS!$F$2:$F$1002 ) ) - SUM( IF( (GIRIS_CIKIS!$B$2:$B$1002="CIKIS")* (GIRIS_CIKIS!$C$2:$C$1002=$A11)* (GIRIS_CIKIS!$D$2:$D$1002=$B11)* (GIRIS_CIKIS!$E$2:$E$1002="MAVI"), GIRIS_CIKIS!$F$2:$F$1002 ) ),0)} -> 0 | P11: =SUM(C11:O11) -> 12 | Q11: ADET
A12: KOCAKPARK | B12: H:100CM IKILI DUZ KAYDIRAK | C12: {=IFERROR( SUM( IF( (GIRIS_CIKIS!$B$2:$B$1002="GIRIS")* (GIRIS_CIKIS!$C$2:$C$1002=$A12)* (GIRIS_CIKIS!$D$2:$D$1002=$B12)* (GIRIS_CIKIS!$E$2:$E$1002="DALDIRMA"), GIRIS_CIKIS!$F$2:$F$1002 ) ) - SUM( IF( (GIRIS_CIKIS!$B$2:$B$1002="CIKIS")* (GIRIS_CIKIS!$C$2:$C$1002=$A12)* (GIRIS_CIKIS!$D$2:$D$1002=$B12)* (GIRIS_CIKIS!$E$2:$E$1002="DALDIRMA"), GIRIS_CIKIS!$F$2:$F$1002 ) ),0)} -> 0 | D12: {=IFERROR( SUM( IF( (GIRIS_CIKIS!$B$2:$B$1002="GIRIS")* (GIRIS_CIKIS!$C$2:$C$1002=$A12)* (GIRIS_CIKIS!$D$2:$D$1002=$B12)* (GIRIS_CIKIS!$E$2:$E$1002="YESIL"), GIRIS_CIKIS!$F$2:$F$1002 ) ) - SUM( IF( (GIRIS_CIKIS!$B$2:$B$1002="CIKIS")* (GIRIS_CIKIS!$C$2:$C$1002=$A12)* (GIRIS_CIKIS!$D$2:$D$1002=$B12)* (GIRIS_CIKIS!$E$2:$E$1002="YESIL"), GIRIS_CIKIS!$F$2:$F$1002 ) ),0)} -> 1 | E12: {=IFERROR( SUM( IF( (GIRIS_CIKIS!$B$2:$B$1002="GIRIS")* (GIRIS_CIKIS!$C$2:$C$1002=$A12)* (GIRIS_CIKIS!$D$2:$D$1002=$B12)* (GIRIS_CIKIS!$E$2:$E$1002="MOR"), GIRIS_CIKIS!$F$2:$F$1002 ) ) - SUM( IF( (GIRIS_CIKIS!$B$2:$B$1002="CIKIS")* (GIRIS_CIKIS!$C$2:$C$1002=$A12)* (GIRIS_CIKIS!$D$2:$D$1002=$B12)* (GIRIS_CIKIS!$E$2:$E$1002="MOR"), GIRIS_CIKIS!$F$2:$F$1002 ) ),0)} -> 0 | F12: {=IFERROR( SUM( IF( (GIRIS_CIKIS!$B$2:$B$1002="GIRIS")* (GIRIS_CIKIS!$C$2:$C$1002=$A12)* (GIRIS_CIKIS!$D$2:$D$1002=$B12)* (GIRIS_CIKIS!$E$2:$E$1002="ACIK SARI"), GIRIS_CIKIS!$F$2:$F$1002 ) ) - SUM( IF( (GIRIS_CIKIS!$B$2:$B$1002="CIKIS")* (GIRIS_CIKIS!$C$2:$C$1002=$A12)* (GIRIS_CIKIS!$D$2:$D$1002=$B12)* (GIRIS_CIKIS!$E$2:$E$1002="ACIK SARI"), GIRIS_CIKIS!$F$2:$F$1002 ) ),0)} -> 0 | G12: {=IFERROR( SUM( IF( (GIRIS_CIKIS!$B$2:$B$1002="GIRIS")* (GIRIS_CIKIS!$C$2:$C$1002=$A12)* (GIRIS_CIKIS!$D$2:$D$1002=$B12)* (GIRIS_CIKIS!$E$2:$E$1002="SARI"), GIRIS_CIKIS!$F$2:$F$1002 ) ) - SUM( IF( (GIRIS_CIKIS!$B$2:$B$1002="CIKIS")* (GIRIS_CIKIS!$C$2:$C$1002=$A12)* (GIRIS_CIKIS!$D$2:$D$1002=$B12)* (GIRIS_CIKIS!$E$2:$E$1002="SARI"), GIRIS_CIKIS!$F$2:$F$1002 ) ),0)} -> 8 | H12: {=IFERROR( SUM( IF( (GIRIS_CIKIS!$B$2:$B$1002="GIRIS")* (GIRIS_CIKIS!$C$2:$C$1002=$A12)* (GIRIS_CIKIS!$D$2:$D$1002=$B12)* (GIRIS_CIKIS!$E$2:$E$1002="TURUNCU"), GIRIS_CIKIS!$F$2:$F$1002 ) ) - SUM( IF( (GIRIS_CIKIS!$B$2:$B$1002="CIKIS")* (GIRIS_CIKIS!$C$2:$C$1002=$A12)* (GIRIS_CIKIS!$D$2:$D$1002=$B12)* (GIRIS_CIKIS!$E$2:$E$1002="TURUNCU"), GIRIS_CIKIS!$F$2:$F$1002 ) ),0)} -> 0 | I12: {=IFERROR( SUM( IF( (GIRIS_CIKIS!$B$2:$B$1002="GIRIS")* (GIRIS_CIKIS!$C$2:$C$1002=$A12)* (GIRIS_CIKIS!$D$2:$D$1002=$B12)* (GIRIS_CIKIS!$E$2:$E$1002="KIRMIZI"), GIRIS_CIKIS!$F$2:$F$1002 ) ) - SUM( IF( (GIRIS_CIKIS!$B$2:$B$1002="CIKIS")* (GIRIS_CIKIS!$C$2:$C$1002=$A12)* (GIRIS_CIKIS!$D$2:$D$1002=$B12)* (GIRIS_CIKIS!$E$2:$E$1002="KIRMIZI"), GIRIS_CIKIS!$F$2:$F$1002 ) ),0)} -> 0 | J12: {=IFERROR( SUM( IF( (GIRIS_CIKIS!$B$2:$B$1002="GIRIS")* (GIRIS_CIKIS!$C$2:$C$1002=$A12)* (GIRIS_CIKIS!$D$2:$D$1002=$B12)* (GIRIS_CIKIS!$E$2:$E$1002="KAHVERENGI"), GIRIS_CIKIS!$F$2:$F$1002 ) ) - SUM( IF( (GIRIS_CIKIS!$B$2:$B$1002="CIKIS")* (GIRIS_CIKIS!$C$2:$C$1002=$A12)* (GIRIS_CIKIS!$D$2:$D$1002=$B12)* (GIRIS_CIKIS!$E$2:$E$1002="KAHVERENGI"), GIRIS_CIKIS!$F$2:$F$1002 ) ),0)} -> 0 | K12: {=IFERROR( SUM( IF( (GIRIS_CIKIS!$B$2:$B$1002="GIRIS")* (GIRIS_CIKIS!$C$2:$C$1002=$A12)* (GIRIS_CIKIS!$D$2:$D$1002=$B12)* (GIRIS_CIKIS!$E$2:$E$1002="ACIK MOR"), GIRIS_CIKIS!$F$2:$F$1002 ) ) - SUM( IF( (GIRIS_CIKIS!$B$2:$B$1002="CIKIS")* (GIRIS_CIKIS!$C$2:$C$1002=$A12)* (GIRIS_CIKIS!$D$2:$D$1002=$B12)* (GIRIS_CIKIS!$E$2:$E$1002="ACIK MOR"), GIRIS_CIKIS!$F$2:$F$1002 ) ),0)} -> 0 | L12: {=IFERROR( SUM( IF( (GIRIS_CIKIS!$B$2:$B$1002="GIRIS")* (GIRIS_CIKIS!$C$2:$C$1002=$A12)* (GIRIS_CIKIS!$D$2:$D$1002=$B12)* (GIRIS_CIKIS!$E$2:$E$1002="GRI"), GIRIS_CIKIS!$F$2:$F$1002 ) ) - SUM( IF( (GIRIS_CIKIS!$B$2:$B$1002="CIKIS")* (GIRIS_CIKIS!$C$2:$C$1002=$A12)* (GIRIS_CIKIS!$D$2:$D$1002=$B12)* (GIRIS_CIKIS!$E$2:$E$1002="GRI"), GIRIS_CIKIS!$F$2:$F$1002 ) ),0)} -> 0 | M12: {=IFERROR( SUM( IF( (GIRIS_CIKIS!$B$2:$B$1002="GIRIS")* (GIRIS_CIKIS!$C$2:$C$1002=$A12)* (GIRIS_CIKIS!$D$2:$D$1002=$B12)* (GIRIS_CIKIS!$E$2:$E$1002="TURKUAZ"), GIRIS_CIKIS!$F$2:$F$1002 ) ) - SUM( IF( (GIRIS_CIKIS!$B$2:$B$1002="CIKIS")* (GIRIS_CIKIS!$C$2:$C$1002=$A12)* (GIRIS_CIKIS!$D$2:$D$1002=$B12)* (GIRIS_CIKIS!$E$2:$E$1002="TURKUAZ"), GIRIS_CIKIS!$F$2:$F$1002 ) ),0)} -> 0 | N12: {=IFERROR( SUM( IF( (GIRIS_CIKIS!$B$2:$B$1002="GIRIS")* (GIRIS_CIKIS!$C$2:$C$1002=$A12)* (GIRIS_CIKIS!$D$2:$D$1002=$B12)* (GIRIS_CIKIS!$E$2:$E$1002="SIYAH"), GIRIS_CIKIS!$F$2:$F$1002 ) ) - SUM( IF( (GIRIS_CIKIS!$B$2:$B$1002="CIKIS")* (GIRIS_CIKIS!$C$2:$C$1002=$A12)* (GIRIS_CIKIS!$D$2:$D$1002=$B12)* (GIRIS_CIKIS!$E$2:$E$1002="SIYAH"), GIRIS_CIKIS!$F$2:$F$1002 ) ),0)} -> 0 | O12: {=IFERROR( SUM( IF( (GIRIS_CIKIS!$B$2:$B$1002="GIRIS")* (GIRIS_CIKIS!$C$2:$C$1002=$A12)* (GIRIS_CIKIS!$D$2:$D$1002=$B12)* (GIRIS_CIKIS!$E$2:$E$1002="MAVI"), GIRIS_CIKIS!$F$2:$F$1002 ) ) - SUM( IF( (GIRIS_CIKIS!$B$2:$B$1002="CIKIS")* (GIRIS_CIKIS!$C$2:$C$1002=$A12)* (GIRIS_CIKIS!$D$2:$D$1002=$B12)* (GIRIS_CIKIS!$E$2:$E$1002="MAVI"), GIRIS_CIKIS!$F$2:$F$1002 ) ),0)} -> 2 | P12: =SUM(C12:O12) -> 11 | Q12: ADET
